#VRML_SIM R2021a utf8
WorldInfo {
  info [
    "A simple RCJ Soccer game simulated using Webots."
  ]
  title "RCJ Soccer Sim"
  optimalThreadCount 8
  coordinateSystem "NUE"
}
Viewpoint {
  orientation 0.9984564522821191 -0.046528037546574474 0.030329105134661388 5.350657005452182
  position 0.15628476627004517 2.490302349685341 1.9602884286189994
}
TexturedBackground {
}
TexturedBackgroundLight {
}
DEF SOCCER_FIELD Solid {
  children [
    DEF GROUND Shape {
      appearance PBRAppearance {
        baseColorMap ImageTexture {
          url [
            "soccer/soccer-256.jpg"
          ]
        }
        roughness 1
        metalness 0
      }
      geometry Plane {
        size 1.5 1.5
      }
    }
    DEF BLUE_GOAL_GROUND Shape {
      appearance PBRAppearance {
        baseColorMap ImageTexture {
          url [
            "soccer/soccer-256.jpg"
          ]
        }
        roughness 1
        metalness 0
      }
      geometry IndexedFaceSet {
        coord Coordinate {
          point [
            0.95 0 0.75
            0.75 0 0.75
            0.75 0 -0.75
            0.95 0 -0.75
          ]
        }
        texCoord TextureCoordinate {
          point [
            0 0
            0 0
            0 0
            0 0
          ]
        }
        ccw FALSE
        coordIndex [
          0, 1, 2, 3
        ]
        texCoordIndex [
          0, 1, 2, 3
        ]
      }
    }
    DEF YELLOW_GOAL_GROUND Shape {
      appearance PBRAppearance {
        baseColorMap ImageTexture {
          url [
            "soccer/soccer-256.jpg"
          ]
        }
        roughness 1
        metalness 0
      }
      geometry IndexedFaceSet {
        coord Coordinate {
          point [
            -0.95 0 0.75
            -0.75 0 0.75
            -0.75 0 -0.75
            -0.95 0 -0.75
          ]
        }
        texCoord TextureCoordinate {
          point [
            0 0
            0 0
            0 0
            0 0
          ]
        }
        coordIndex [
          0, 1, 2, 3
        ]
        texCoordIndex [
          0, 1, 2, 3
        ]
      }
    }
    DEF NORTH_WALL Shape {
      appearance DEF WALL_APPEARANCE PBRAppearance {
        baseColor 0.388235 0.388235 0.388235
        roughness 1
        metalness 0
      }
      geometry IndexedFaceSet {
        coord Coordinate {
          point [
            0.76 0 0.66
            0.76 0 0.21
            0.75 0 0.21
            0.75 0 0.59
            0.69 0 0.65
            -0.69 0 0.65
            -0.75 0 0.59
            -0.75 0 0.21
            -0.76 0 0.21
            -0.76 0 0.65
            -0.76 0 0.66
            0.76 0.05 0.66
            0.76 0.05 0.21
            0.75 0.05 0.21
            0.75 0.05 0.59
            0.69 0.05 0.65
            -0.69 0.05 0.65
            -0.75 0.05 0.59
            -0.75 0.05 0.21
            -0.76 0.05 0.21
            -0.76 0.05 0.65
            -0.76 0.05 0.66
          ]
        }
        coordIndex [
          0, 10, 9, -1, 9, 8, 7, -1, 9, 7, 6, -1, 2, 1, 0, -1, 3, 2, 0, -1, 9, 6, 5, -1, 4, 3, 0, -1, 0, 9, 5, -1, 0, 5, 4, -1, 11, 12, 13, -1, 11, 13, 14, -1, 20, 21, 11, -1, 18, 19, 20, -1, 17, 18, 20, -1, 11, 14, 15, -1, 16, 17, 20, -1, 11, 15, 16, -1, 11, 16, 20, -1, 0, 1, 12, 11, -1, 1, 2, 13, 12, -1, 2, 3, 14, 13, -1, 3, 4, 15, 14, -1, 4, 5, 16, 15, -1, 5, 6, 17, 16, -1, 6, 7, 18, 17, -1, 7, 8, 19, 18, -1, 8, 9, 20, 19, -1, 9, 10, 21, 20, -1, 10, 0, 11, 21, -1
        ]
      }
    }
    DEF SOUTH_WALL Shape {
      appearance USE WALL_APPEARANCE
      geometry IndexedFaceSet {
        coord Coordinate {
          point [
            0.76 0 -0.66
            -0.76 0 -0.66
            -0.76 0 -0.65
            -0.76 0 -0.21
            -0.75 0 -0.21
            -0.75 0 -0.59
            -0.69 0 -0.65
            0.69 0 -0.65
            0.75 0 -0.59
            0.75 0 -0.21
            0.76 0 -0.21
            0.76 0.05 -0.66
            -0.76 0.05 -0.66
            -0.76 0.05 -0.65
            -0.76 0.05 -0.21
            -0.75 0.05 -0.21
            -0.75 0.05 -0.59
            -0.69 0.05 -0.65
            0.69 0.05 -0.65
            0.75 0.05 -0.59
            0.75 0.05 -0.21
            0.76 0.05 -0.21
          ]
        }
        coordIndex [
          0, 10, 9, -1, 0, 9, 8, -1, 2, 1, 0, -1, 4, 3, 2, -1, 5, 4, 2, -1, 0, 8, 7, -1, 6, 5, 2, -1, 0, 7, 6, -1, 0, 6, 2, -1, 11, 12, 13, -1, 13, 14, 15, -1, 13, 15, 16, -1, 20, 21, 11, -1, 19, 20, 11, -1, 13, 16, 17, -1, 18, 19, 11, -1, 11, 13, 17, -1, 11, 17, 18, -1, 0, 1, 12, 11, -1, 1, 2, 13, 12, -1, 2, 3, 14, 13, -1, 3, 4, 15, 14, -1, 4, 5, 16, 15, -1, 5, 6, 17, 16, -1, 6, 7, 18, 17, -1, 7, 8, 19, 18, -1, 8, 9, 20, 19, -1, 9, 10, 21, 20, -1, 10, 0, 11, 21, -1
        ]
      }
    }
    DEF BLUE_GOAL Shape {
      appearance PBRAppearance {
        baseColor 0 0 1
        roughness 1
        metalness 0
      }
      geometry IndexedFaceSet {
        coord Coordinate {
          point [
            0.86 0 0.21
            0.86 0 -0.21
            0.75 0 -0.21
            0.75 0 -0.2
            0.85 0 -0.2
            0.85 0 0.2
            0.75 0 0.2
            0.75 0 0.21
            0.86 0 0.21
            0.86 0.12 0.21
            0.86 0.12 -0.21
            0.75 0.12 -0.21
            0.75 0.12 -0.2
            0.85 0.12 -0.2
            0.85 0.12 0.2
            0.75 0.12 0.2
            0.75 0.12 0.21
            0.86 0.12 0.21
          ]
        }
        coordIndex [
          0, 1, 2, 3, 4, 5, 6, 7, 8, -1, 0, 1, 10, 9, -1, 1, 2, 11, 10, -1, 2, 3, 12, 11, -1, 3, 4, 13, 12, -1, 4, 5, 14, 13, -1, 5, 6, 15, 14, -1, 6, 7, 16, 15, -1, 7, 8, 17, 16, -1
        ]
      }
    }
    DEF YELLOW_GOAL Shape {
      appearance PBRAppearance {
        baseColor 1 1 0
        roughness 1
        metalness 0
      }
      geometry IndexedFaceSet {
        coord Coordinate {
          point [
            -0.86 0 0.21
            -0.75 0 0.21
            -0.75 0 0.2
            -0.85 0 0.2
            -0.85 0 -0.2
            -0.75 0 -0.2
            -0.75 0 -0.21
            -0.86 0 -0.21
            -0.86 0 0.21
            -0.86 0.12 0.21
            -0.75 0.12 0.21
            -0.75 0.12 0.2
            -0.85 0.12 0.2
            -0.85 0.12 -0.2
            -0.75 0.12 -0.2
            -0.75 0.12 -0.21
            -0.86 0.12 -0.21
            -0.86 0.12 0.21
          ]
        }
        coordIndex [
          0, 1, 2, 3, 4, 5, 6, 7, 8, -1, 0, 1, 10, 9, -1, 1, 2, 11, 10, -1, 2, 3, 12, 11, -1, 3, 4, 13, 12, -1, 4, 5, 14, 13, -1, 5, 6, 15, 14, -1, 6, 7, 16, 15, -1, 7, 8, 17, 16, -1
        ]
      }
    }
  ]
  name "soccer field"
  boundingObject Group {
    children [
      USE GROUND
      DEF NOTH_BBOX Transform {
        translation 0 0.0251 -0.655
        children [
          Box {
            size 1.5 0.05 0.01
          }
        ]
      }
      DEF SOUTH_BBOX Transform {
        translation 0 0.0251 0.655
        children [
          Box {
            size 1.5 0.05 0.01
          }
        ]
      }
      DEF NW_BBOX Transform {
        translation -0.755 0.0251 -0.43
        children [
          Box {
            size 0.01 0.05 0.435
          }
        ]
      }
      DEF NE_BBOX Transform {
        translation 0.755 0.0251 -0.43
        children [
          Box {
            size 0.01 0.05 0.435
          }
        ]
      }
      DEF SW_BBOX Transform {
        translation -0.755 0.0251 0.43
        children [
          Box {
            size 0.01 0.05 0.435
          }
        ]
      }
      DEF SE_BBOX Transform {
        translation 0.755 0.0251 0.43
        children [
          Box {
            size 0.01 0.05 0.435
          }
        ]
      }
      DEF NWC_BBOX Transform {
        translation 0.725 0.0251 0.62
        rotation 0 1 0 -0.7853
        children [
          Box {
            size 0.01 0.05 0.09
          }
        ]
      }
      DEF NEC_BBOX Transform {
        translation -0.725 0.0251 0.62
        rotation 0 1 0 0.7853
        children [
          Box {
            size 0.01 0.05 0.09
          }
        ]
      }
      DEF SWC_BBOX Transform {
        translation 0.725 0.0251 -0.62
        rotation 0 1 0 0.7853
        children [
          Box {
            size 0.01 0.05 0.09
          }
        ]
      }
      DEF SEC_BBOX Transform {
        translation -0.725 0.0251 -0.62
        rotation 0 1 0 -0.7853
        children [
          Box {
            size 0.01 0.05 0.09
          }
        ]
      }
      DEF YG_BBOX Transform {
        translation -0.855 0.061 0
        children [
          Box {
            size 0.01 0.12 0.42
          }
        ]
      }
      DEF BG_BBOX Transform {
        translation 0.855 0.061 0
        children [
          Box {
            size 0.01 0.12 0.42
          }
        ]
      }
      DEF BGS_BBOX Transform {
        translation 0.8 0.061 0.205
        children [
          Box {
            size 0.1 0.12 0.01
          }
        ]
      }
      DEF BGN_BBOX Transform {
        translation 0.8 0.061 -0.205
        children [
          Box {
            size 0.1 0.12 0.01
          }
        ]
      }
      DEF YGS_BBOX Transform {
        translation -0.8 0.061 0.205
        children [
          Box {
            size 0.1 0.12 0.01
          }
        ]
      }
      DEF YGN_BBOX Transform {
        translation -0.8 0.061 -0.205
        children [
          Box {
            size 0.1 0.12 0.01
          }
        ]
      }
    ]
  }
  locked TRUE
}
DEF BALL SoccerBall {
  translation -0.489991 0.0209215 -0.043541
  rotation 0.7013517222575323 0.028995707853865887 0.7122253931252708 2.5658663734186034
  radius 0.021
  mass 0.05
}
DEF B1 Robot {
  translation 0.42332837851292143 0.0375160375707073 0.7113136652561891
  rotation -0.0002018467710055476 -0.9999999577157174 -0.0002093476647758603 1.6333756023796897
  children [
    HingeJoint {
      jointParameters HingeJointParameters {
        position -0.7672816984570487
        axis -1 0 0
        anchor 0.045 -0.0176 0
      }
      device [
        RotationalMotor {
          name "left wheel motor"
        }
        PositionSensor {
          name "left wheel sensor"
        }
      ]
      endPoint Solid {
        translation 0.045 -0.0176 0
        rotation 1 0 0 1.2941666984570492
        children [
          Transform {
            rotation 0 0 1 1.57
            children [
              DEF WHEEL_SHAPE Shape {
                appearance PBRAppearance {
                  roughness 1
                  metalness 0
                }
                geometry Cylinder {
                  height 0.01
                  radius 0.02
                }
              }
            ]
          }
        ]
        name "right wheel"
        boundingObject Transform {
          rotation 0 0 1 1.57
          children [
            USE WHEEL_SHAPE
          ]
        }
        physics DEF WHEEL_PHYSICS Physics {
          density -1
          mass 0.005
        }
      }
    }
    HingeJoint {
      jointParameters HingeJointParameters {
        position 0.7672817391756701
        axis -1 0 0
        anchor -0.045 -0.0176 0
      }
      device [
        RotationalMotor {
          name "right wheel motor"
        }
        PositionSensor {
          name "right wheel sensor"
        }
      ]
      endPoint Solid {
        translation -0.045 -0.0176 0
        rotation -0.9999999999999999 0 0 0.24122773917566873
        children [
          Transform {
            rotation 0 0 1 1.57
            children [
              Shape {
                appearance PBRAppearance {
                  roughness 1
                  metalness 0
                }
                geometry Cylinder {
                  height 0.01
                  radius 0.02
                }
              }
            ]
          }
        ]
        name "left wheel"
        boundingObject Transform {
          rotation 0 0 1 1.57
          children [
            Shape {
              appearance PBRAppearance {
                roughness 1
                metalness 0
              }
              geometry Cylinder {
                height 0.01
                radius 0.02
              }
            }
          ]
        }
        physics USE WHEEL_PHYSICS
      }
    }
    DEF BLUE_ROBOT_SHAPE Shape {
      appearance PBRAppearance {
        baseColorMap ImageTexture {
          url [
            "soccer/blue.png"
          ]
        }
        roughness 1
        metalness 0
      }
      geometry Box {
        size 0.075 0.075 0.075
      }
    }
    Receiver {
    }
  ]
  name "B1"
  boundingObject USE BLUE_ROBOT_SHAPE
  physics DEF ROBOT_PHYSICS Physics {
    density -1
    mass 0.2
  }
  controller "rcj_soccer_team_blue"
  synchronization FALSE
  linearVelocity -1.2931218177043272e-11 1.8480856407228746e-12 3.0475348786303467e-12
  angularVelocity 5.824701580900153e-11 1.3618527852962157e-10 -2.8000966724617494e-10
}
DEF B2 Robot {
  translation 0.26215470008604114 0.037516037581610526 0.7110226103906135
  rotation -0.00021982815524638246 0.9999999527581158 -0.00021484726679476068 -1.5223401913000647
  children [
    HingeJoint {
      jointParameters HingeJointParameters {
        position 0.7673579492246877
        axis -1 0 0
        anchor 0.045 -0.0176 0
      }
      device [
        RotationalMotor {
          name "left wheel motor"
        }
        PositionSensor {
          name "left wheel sensor"
        }
      ]
      endPoint Solid {
        translation 0.045 -0.0176 0
        rotation -1 0 0 0.24047294922468504
        children [
          Transform {
            rotation 0 0 1 1.57
            children [
              DEF WHEEL_SHAPE Shape {
                appearance PBRAppearance {
                  roughness 1
                  metalness 0
                }
                geometry Cylinder {
                  height 0.01
                  radius 0.02
                }
              }
            ]
          }
        ]
        name "right wheel"
        boundingObject Transform {
          rotation 0 0 1 1.57
          children [
            USE WHEEL_SHAPE
          ]
        }
        physics DEF WHEEL_PHYSICS Physics {
          density -1
          mass 0.005
        }
      }
    }
    HingeJoint {
      jointParameters HingeJointParameters {
        position -0.7673579680562402
        axis -1 0 0
        anchor -0.045 -0.0176 0
      }
      device [
        RotationalMotor {
          name "right wheel motor"
        }
        PositionSensor {
          name "right wheel sensor"
        }
      ]
      endPoint Solid {
        translation -0.045 -0.0176 0
        rotation 1 0 0 1.2934119680562397
        children [
          Transform {
            rotation 0 0 1 1.57
            children [
              Shape {
                appearance PBRAppearance {
                  roughness 1
                  metalness 0
                }
                geometry Cylinder {
                  height 0.01
                  radius 0.02
                }
              }
            ]
          }
        ]
        name "left wheel"
        boundingObject Transform {
          rotation 0 0 1 1.57
          children [
            Shape {
              appearance PBRAppearance {
                roughness 1
                metalness 0
              }
              geometry Cylinder {
                height 0.01
                radius 0.02
              }
            }
          ]
        }
        physics USE WHEEL_PHYSICS
      }
    }
    DEF BLUE_ROBOT_SHAPE Shape {
      appearance PBRAppearance {
        baseColorMap ImageTexture {
          url [
            "soccer/blue.png"
          ]
        }
        roughness 1
        metalness 0
      }
      geometry Box {
        size 0.075 0.075 0.075
      }
    }
    Receiver {
    }
  ]
  name "B2"
  boundingObject USE BLUE_ROBOT_SHAPE
  physics USE ROBOT_PHYSICS
  controller "rcj_soccer_team_blue"
  synchronization FALSE
  linearVelocity 2.9559096143632786e-11 9.731591252504182e-13 -1.0576368765556033e-11
  angularVelocity 1.512795542170945e-11 5.685016708204825e-10 1.3510111016739035e-10
}
DEF B3 Robot {
  translation 0.08032457720092571 0.03751604604091428 0.7100238291552693
  rotation -0.0002150724346847468 0.9999999728715837 8.944651908410694e-05 -1.5701126784424981
  children [
    HingeJoint {
      jointParameters HingeJointParameters {
        position -0.9600000176047533
        axis -1 0 0
        anchor 0.045 -0.0176 0
      }
      device [
        RotationalMotor {
          name "left wheel motor"
        }
        PositionSensor {
          name "left wheel sensor"
        }
      ]
      endPoint Solid {
        translation 0.045 -0.0176 0
        rotation 0.9999999999999999 0 0 1.486885017604753
        children [
          Transform {
            rotation 0 0 1 1.57
            children [
              DEF WHEEL_SHAPE Shape {
                appearance PBRAppearance {
                  roughness 1
                  metalness 0
                }
                geometry Cylinder {
                  height 0.01
                  radius 0.02
                }
              }
            ]
          }
        ]
        name "right wheel"
        boundingObject Transform {
          rotation 0 0 1 1.57
          children [
            USE WHEEL_SHAPE
          ]
        }
        physics DEF WHEEL_PHYSICS Physics {
          density -1
          mass 0.005
        }
      }
    }
    HingeJoint {
      jointParameters HingeJointParameters {
        position -0.9599999679297039
        axis -1 0 0
        anchor -0.045 -0.0176 0
      }
      device [
        RotationalMotor {
          name "right wheel motor"
        }
        PositionSensor {
          name "right wheel sensor"
        }
      ]
      endPoint Solid {
        translation -0.045 -0.0176 0
        rotation 1 0 0 1.486053967929703
        children [
          Transform {
            rotation 0 0 1 1.57
            children [
              Shape {
                appearance PBRAppearance {
                  roughness 1
                  metalness 0
                }
                geometry Cylinder {
                  height 0.01
                  radius 0.02
                }
              }
            ]
          }
        ]
        name "left wheel"
        boundingObject Transform {
          rotation 0 0 1 1.57
          children [
            Shape {
              appearance PBRAppearance {
                roughness 1
                metalness 0
              }
              geometry Cylinder {
                height 0.01
                radius 0.02
              }
            }
          ]
        }
        physics USE WHEEL_PHYSICS
      }
    }
    DEF BLUE_ROBOT_SHAPE Shape {
      appearance PBRAppearance {
        baseColorMap ImageTexture {
          url [
            "soccer/blue.png"
          ]
        }
        roughness 1
        metalness 0
      }
      geometry Box {
        size 0.075 0.075 0.075
      }
    }
    Receiver {
    }
  ]
  name "B3"
  boundingObject USE BLUE_ROBOT_SHAPE
  physics USE ROBOT_PHYSICS
  controller "rcj_soccer_team_blue"
  synchronization FALSE
  linearVelocity -1.370559367231057e-05 2.38802753287264e-07 -1.1457339529294791e-05
  angularVelocity -0.0003648181528619305 -1.443045086972398e-05 0.00036472246518124275
}
DEF Y1 Robot {
  translation -0.33851256084028775 0.03751603758129823 0.7113259235514773
  rotation 0.00022877183197754378 0.9999999519912129 -0.0002090000497592664 1.5066141018812875
  children [
    HingeJoint {
      jointParameters HingeJointParameters {
        position -0.7672816484311697
        axis -1 0 0
        anchor 0.045 -0.0176 0
      }
      device [
        RotationalMotor {
          name "left wheel motor"
        }
        PositionSensor {
          name "left wheel sensor"
        }
      ]
      endPoint Solid {
        translation 0.045 -0.0176 0
        rotation 1 0 0 1.2941666484311691
        children [
          Transform {
            rotation 0 0 1 1.57
            children [
              DEF WHEEL_SHAPE Shape {
                appearance PBRAppearance {
                  roughness 1
                  metalness 0
                }
                geometry Cylinder {
                  height 0.01
                  radius 0.02
                }
              }
            ]
          }
        ]
        name "right wheel"
        boundingObject Transform {
          rotation 0 0 1 1.57
          children [
            USE WHEEL_SHAPE
          ]
        }
        physics DEF WHEEL_PHYSICS Physics {
          density -1
          mass 0.005
        }
      }
    }
    HingeJoint {
      jointParameters HingeJointParameters {
        position 0.7672816890857415
        axis -1 0 0
        anchor -0.045 -0.0176 0
      }
      device [
        RotationalMotor {
          name "right wheel motor"
        }
        PositionSensor {
          name "right wheel sensor"
        }
      ]
      endPoint Solid {
        translation -0.045 -0.0176 0
        rotation -1 0 0 0.24122768908574074
        children [
          Transform {
            rotation 0 0 1 1.57
            children [
              Shape {
                appearance PBRAppearance {
                  roughness 1
                  metalness 0
                }
                geometry Cylinder {
                  height 0.01
                  radius 0.02
                }
              }
            ]
          }
        ]
        name "left wheel"
        boundingObject Transform {
          rotation 0 0 1 1.57
          children [
            Shape {
              appearance PBRAppearance {
                roughness 1
                metalness 0
              }
              geometry Cylinder {
                height 0.01
                radius 0.02
              }
            }
          ]
        }
        physics USE WHEEL_PHYSICS
      }
    }
    DEF YELLOW_ROBOT_SHAPE Shape {
      appearance PBRAppearance {
        baseColorMap ImageTexture {
          url [
            "soccer/yellow.png"
          ]
        }
        roughness 1
        metalness 0
      }
      geometry Box {
        size 0.075 0.075 0.075
      }
    }
    Receiver {
    }
  ]
  name "Y1"
  boundingObject USE YELLOW_ROBOT_SHAPE
  physics USE ROBOT_PHYSICS
  controller "rcj_soccer_team_yellow"
  synchronization FALSE
  linearVelocity 1.2794131597708507e-11 -1.827374186015795e-12 4.407177504404606e-12
  angularVelocity 1.5284655187231902e-11 1.3809849755457572e-10 2.7664690296971014e-10
}
DEF Y2 Robot {
  translation -0.2022785673081374 0.03751603758161212 0.7109849307092332
  rotation -0.0002194742424501841 0.9999999528368244 -0.0002148427472857431 -1.5239300151872572
  children [
    HingeJoint {
      jointParameters HingeJointParameters {
        position 0.7673579400879401
        axis -1 0 0
        anchor 0.045 -0.0176 0
      }
      device [
        RotationalMotor {
          name "left wheel motor"
        }
        PositionSensor {
          name "left wheel sensor"
        }
      ]
      endPoint Solid {
        translation 0.045 -0.0176 0
        rotation -0.9999999999999999 0 0 0.24047294008794023
        children [
          Transform {
            rotation 0 0 1 1.57
            children [
              DEF WHEEL_SHAPE Shape {
                appearance PBRAppearance {
                  roughness 1
                  metalness 0
                }
                geometry Cylinder {
                  height 0.01
                  radius 0.02
                }
              }
            ]
          }
        ]
        name "right wheel"
        boundingObject Transform {
          rotation 0 0 1 1.57
          children [
            USE WHEEL_SHAPE
          ]
        }
        physics DEF WHEEL_PHYSICS Physics {
          density -1
          mass 0.005
        }
      }
    }
    HingeJoint {
      jointParameters HingeJointParameters {
        position -0.7673579589601398
        axis -1 0 0
        anchor -0.045 -0.0176 0
      }
      device [
        RotationalMotor {
          name "right wheel motor"
        }
        PositionSensor {
          name "right wheel sensor"
        }
      ]
      endPoint Solid {
        translation -0.045 -0.0176 0
        rotation 1 0 0 1.2934119589601392
        children [
          Transform {
            rotation 0 0 1 1.57
            children [
              Shape {
                appearance PBRAppearance {
                  roughness 1
                  metalness 0
                }
                geometry Cylinder {
                  height 0.01
                  radius 0.02
                }
              }
            ]
          }
        ]
        name "left wheel"
        boundingObject Transform {
          rotation 0 0 1 1.57
          children [
            Shape {
              appearance PBRAppearance {
                roughness 1
                metalness 0
              }
              geometry Cylinder {
                height 0.01
                radius 0.02
              }
            }
          ]
        }
        physics USE WHEEL_PHYSICS
      }
    }
    DEF YELLOW_ROBOT_SHAPE Shape {
      appearance PBRAppearance {
        baseColorMap ImageTexture {
          url [
            "soccer/yellow.png"
          ]
        }
        roughness 1
        metalness 0
      }
      geometry Box {
        size 0.075 0.075 0.075
      }
    }
    Receiver {
    }
  ]
  name "Y2"
  boundingObject USE YELLOW_ROBOT_SHAPE
  physics USE ROBOT_PHYSICS
  controller "rcj_soccer_team_yellow"
  synchronization FALSE
  linearVelocity 2.965219943081337e-11 9.701393521857918e-13 -1.053044301670253e-11
  angularVelocity 1.484578550923309e-11 5.671221970592595e-10 1.3481433253885137e-10
}
DEF Y3 Robot {
  translation -0.5890450995138644 0.03751604088197461 -0.060963367572112244
  rotation 0.00021480432827156073 0.9999999540189851 -0.0002140587025456273 1.5700015281335888
  children [
    HingeJoint {
      jointParameters HingeJointParameters {
        position -0.9600000030933294
        axis -1 0 0
        anchor 0.045 -0.0176 0
      }
      device [
        RotationalMotor {
          name "left wheel motor"
        }
        PositionSensor {
          name "left wheel sensor"
        }
      ]
      endPoint Solid {
        translation 0.045 -0.0176 0
        rotation 1 0 0 1.486885003093328
        children [
          Transform {
            rotation 0 0 1 1.57
            children [
              DEF WHEEL_SHAPE Shape {
                appearance PBRAppearance {
                  roughness 1
                  metalness 0
                }
                geometry Cylinder {
                  height 0.01
                  radius 0.02
                }
              }
            ]
          }
        ]
        name "right wheel"
        boundingObject Transform {
          rotation 0 0 1 1.57
          children [
            USE WHEEL_SHAPE
          ]
        }
        physics DEF WHEEL_PHYSICS Physics {
          density -1
          mass 0.005
        }
      }
    }
    HingeJoint {
      jointParameters HingeJointParameters {
        position -0.9599999937363127
        axis -1 0 0
        anchor -0.045 -0.0176 0
      }
      device [
        RotationalMotor {
          name "right wheel motor"
        }
        PositionSensor {
          name "right wheel sensor"
        }
      ]
      endPoint Solid {
        translation -0.045 -0.0176 0
        rotation 1 0 0 1.4860539937363115
        children [
          Transform {
            rotation 0 0 1 1.57
            children [
              Shape {
                appearance PBRAppearance {
                  roughness 1
                  metalness 0
                }
                geometry Cylinder {
                  height 0.01
                  radius 0.02
                }
              }
            ]
          }
        ]
        name "left wheel"
        boundingObject Transform {
          rotation 0 0 1 1.57
          children [
            Shape {
              appearance PBRAppearance {
                roughness 1
                metalness 0
              }
              geometry Cylinder {
                height 0.01
                radius 0.02
              }
            }
          ]
        }
        physics USE WHEEL_PHYSICS
      }
    }
    DEF YELLOW_ROBOT_SHAPE Shape {
      appearance PBRAppearance {
        baseColorMap ImageTexture {
          url [
            "soccer/yellow.png"
          ]
        }
        roughness 1
        metalness 0
      }
      geometry Box {
        size 0.075 0.075 0.075
      }
    }
    Receiver {
    }
  ]
  name "Y3"
  boundingObject USE YELLOW_ROBOT_SHAPE
  physics USE ROBOT_PHYSICS
  controller "score_goal"
  synchronization FALSE
  linearVelocity -1.9577984841220981e-13 -1.100913921589819e-14 1.0681099253973492e-13
  angularVelocity 3.0268247305129773e-13 -2.773237274646795e-12 2.0810287665262364e-12
}
Robot {
  children [
    Emitter {
      range 10
      baudRate 115200
    }
  ]
  controller "rcj_soccer_referee_supervisor"
  supervisor TRUE
  synchronization TRUE
}
