#VRML_SIM R2020b utf8
WorldInfo {
  info [
    "A soccer game."
    "This example demonstrates several capabilities of the supervisor:"
    "- read and modify the position of objects"
    "- display text on the simulation window"
    "- send messages to robot controllers"
  ]
  title "Soccer Game"
  optimalThreadCount 8
  coordinateSystem "NUE"
}
Viewpoint {
  orientation 0.24186178906808894 -0.8865744678432691 -0.39432041280817226 4.031210748340835
  position 0.7070988875089543 0.951104656870603 -0.5218715809909629
}
TexturedBackground {
}
TexturedBackgroundLight {
}
DEF SOCCER_FIELD Solid {
  children [
    DEF GROUND Shape {
      appearance PBRAppearance {
        baseColorMap ImageTexture {
          url [
            "soccer/soccer-256.jpg"
          ]
        }
        roughness 1
        metalness 0
      }
      geometry Plane {
        size 1.5 1.5
      }
    }
    DEF BLUE_GOAL_GROUND Shape {
      appearance PBRAppearance {
        baseColorMap ImageTexture {
          url [
            "soccer/soccer-256.jpg"
          ]
        }
        roughness 1
        metalness 0
      }
      geometry IndexedFaceSet {
        coord Coordinate {
          point [
            0.95 0 0.75
            0.75 0 0.75
            0.75 0 -0.75
            0.95 0 -0.75
          ]
        }
        texCoord TextureCoordinate {
          point [
            0 0
            0 0
            0 0
            0 0
          ]
        }
        ccw FALSE
        coordIndex [
          0, 1, 2, 3
        ]
        texCoordIndex [
          0, 1, 2, 3
        ]
      }
    }
    DEF YELLOW_GOAL_GROUND Shape {
      appearance PBRAppearance {
        baseColorMap ImageTexture {
          url [
            "soccer/soccer-256.jpg"
          ]
        }
        roughness 1
        metalness 0
      }
      geometry IndexedFaceSet {
        coord Coordinate {
          point [
            -0.95 0 0.75
            -0.75 0 0.75
            -0.75 0 -0.75
            -0.95 0 -0.75
          ]
        }
        texCoord TextureCoordinate {
          point [
            0 0
            0 0
            0 0
            0 0
          ]
        }
        coordIndex [
          0, 1, 2, 3
        ]
        texCoordIndex [
          0, 1, 2, 3
        ]
      }
    }
    DEF NORTH_WALL Shape {
      appearance DEF WALL_APPEARANCE PBRAppearance {
        baseColor 0.388235 0.388235 0.388235
        roughness 1
        metalness 0
      }
      geometry IndexedFaceSet {
        coord Coordinate {
          point [
            0.76 0 0.66
            0.76 0 0.21
            0.75 0 0.21
            0.75 0 0.59
            0.69 0 0.65
            -0.69 0 0.65
            -0.75 0 0.59
            -0.75 0 0.21
            -0.76 0 0.21
            -0.76 0 0.65
            -0.76 0 0.66
            0.76 0.05 0.66
            0.76 0.05 0.21
            0.75 0.05 0.21
            0.75 0.05 0.59
            0.69 0.05 0.65
            -0.69 0.05 0.65
            -0.75 0.05 0.59
            -0.75 0.05 0.21
            -0.76 0.05 0.21
            -0.76 0.05 0.65
            -0.76 0.05 0.66
          ]
        }
        coordIndex [
          0, 10, 9, -1, 9, 8, 7, -1, 9, 7, 6, -1, 2, 1, 0, -1, 3, 2, 0, -1, 9, 6, 5, -1, 4, 3, 0, -1, 0, 9, 5, -1, 0, 5, 4, -1, 11, 12, 13, -1, 11, 13, 14, -1, 20, 21, 11, -1, 18, 19, 20, -1, 17, 18, 20, -1, 11, 14, 15, -1, 16, 17, 20, -1, 11, 15, 16, -1, 11, 16, 20, -1, 0, 1, 12, 11, -1, 1, 2, 13, 12, -1, 2, 3, 14, 13, -1, 3, 4, 15, 14, -1, 4, 5, 16, 15, -1, 5, 6, 17, 16, -1, 6, 7, 18, 17, -1, 7, 8, 19, 18, -1, 8, 9, 20, 19, -1, 9, 10, 21, 20, -1, 10, 0, 11, 21, -1
        ]
      }
    }
    DEF SOUTH_WALL Shape {
      appearance USE WALL_APPEARANCE
      geometry IndexedFaceSet {
        coord Coordinate {
          point [
            0.76 0 -0.66
            -0.76 0 -0.66
            -0.76 0 -0.65
            -0.76 0 -0.21
            -0.75 0 -0.21
            -0.75 0 -0.59
            -0.69 0 -0.65
            0.69 0 -0.65
            0.75 0 -0.59
            0.75 0 -0.21
            0.76 0 -0.21
            0.76 0.05 -0.66
            -0.76 0.05 -0.66
            -0.76 0.05 -0.65
            -0.76 0.05 -0.21
            -0.75 0.05 -0.21
            -0.75 0.05 -0.59
            -0.69 0.05 -0.65
            0.69 0.05 -0.65
            0.75 0.05 -0.59
            0.75 0.05 -0.21
            0.76 0.05 -0.21
          ]
        }
        coordIndex [
          0, 10, 9, -1, 0, 9, 8, -1, 2, 1, 0, -1, 4, 3, 2, -1, 5, 4, 2, -1, 0, 8, 7, -1, 6, 5, 2, -1, 0, 7, 6, -1, 0, 6, 2, -1, 11, 12, 13, -1, 13, 14, 15, -1, 13, 15, 16, -1, 20, 21, 11, -1, 19, 20, 11, -1, 13, 16, 17, -1, 18, 19, 11, -1, 11, 13, 17, -1, 11, 17, 18, -1, 0, 1, 12, 11, -1, 1, 2, 13, 12, -1, 2, 3, 14, 13, -1, 3, 4, 15, 14, -1, 4, 5, 16, 15, -1, 5, 6, 17, 16, -1, 6, 7, 18, 17, -1, 7, 8, 19, 18, -1, 8, 9, 20, 19, -1, 9, 10, 21, 20, -1, 10, 0, 11, 21, -1
        ]
      }
    }
    DEF BLUE_GOAL Shape {
      appearance PBRAppearance {
        baseColor 0 0 1
        roughness 1
        metalness 0
      }
      geometry IndexedFaceSet {
        coord Coordinate {
          point [
            0.86 0 0.21
            0.86 0 -0.21
            0.75 0 -0.21
            0.75 0 -0.2
            0.85 0 -0.2
            0.85 0 0.2
            0.75 0 0.2
            0.75 0 0.21
            0.86 0 0.21
            0.86 0.12 0.21
            0.86 0.12 -0.21
            0.75 0.12 -0.21
            0.75 0.12 -0.2
            0.85 0.12 -0.2
            0.85 0.12 0.2
            0.75 0.12 0.2
            0.75 0.12 0.21
            0.86 0.12 0.21
          ]
        }
        coordIndex [
          0, 1, 2, 3, 4, 5, 6, 7, 8, -1, 0, 1, 10, 9, -1, 1, 2, 11, 10, -1, 2, 3, 12, 11, -1, 3, 4, 13, 12, -1, 4, 5, 14, 13, -1, 5, 6, 15, 14, -1, 6, 7, 16, 15, -1, 7, 8, 17, 16, -1
        ]
      }
    }
    DEF YELLOW_GOAL Shape {
      appearance PBRAppearance {
        baseColor 1 1 0
        roughness 1
        metalness 0
      }
      geometry IndexedFaceSet {
        coord Coordinate {
          point [
            -0.86 0 0.21
            -0.75 0 0.21
            -0.75 0 0.2
            -0.85 0 0.2
            -0.85 0 -0.2
            -0.75 0 -0.2
            -0.75 0 -0.21
            -0.86 0 -0.21
            -0.86 0 0.21
            -0.86 0.12 0.21
            -0.75 0.12 0.21
            -0.75 0.12 0.2
            -0.85 0.12 0.2
            -0.85 0.12 -0.2
            -0.75 0.12 -0.2
            -0.75 0.12 -0.21
            -0.86 0.12 -0.21
            -0.86 0.12 0.21
          ]
        }
        coordIndex [
          0, 1, 2, 3, 4, 5, 6, 7, 8, -1, 0, 1, 10, 9, -1, 1, 2, 11, 10, -1, 2, 3, 12, 11, -1, 3, 4, 13, 12, -1, 4, 5, 14, 13, -1, 5, 6, 15, 14, -1, 6, 7, 16, 15, -1, 7, 8, 17, 16, -1
        ]
      }
    }
  ]
  name "soccer field"
  boundingObject Group {
    children [
      USE GROUND
      DEF NOTH_BBOX Transform {
        translation 0 0.0251 -0.655
        children [
          Box {
            size 1.5 0.05 0.01
          }
        ]
      }
      DEF SOUTH_BBOX Transform {
        translation 0 0.0251 0.655
        children [
          Box {
            size 1.5 0.05 0.01
          }
        ]
      }
      DEF NW_BBOX Transform {
        translation -0.755 0.0251 -0.43
        children [
          Box {
            size 0.01 0.05 0.435
          }
        ]
      }
      DEF NE_BBOX Transform {
        translation 0.755 0.0251 -0.43
        children [
          Box {
            size 0.01 0.05 0.435
          }
        ]
      }
      DEF SW_BBOX Transform {
        translation -0.755 0.0251 0.43
        children [
          Box {
            size 0.01 0.05 0.435
          }
        ]
      }
      DEF SE_BBOX Transform {
        translation 0.755 0.0251 0.43
        children [
          Box {
            size 0.01 0.05 0.435
          }
        ]
      }
      DEF NWC_BBOX Transform {
        translation 0.725 0.0251 0.62
        rotation 0 1 0 -0.7853
        children [
          Box {
            size 0.01 0.05 0.09
          }
        ]
      }
      DEF NEC_BBOX Transform {
        translation -0.725 0.0251 0.62
        rotation 0 1 0 0.7853
        children [
          Box {
            size 0.01 0.05 0.09
          }
        ]
      }
      DEF SWC_BBOX Transform {
        translation 0.725 0.0251 -0.62
        rotation 0 1 0 0.7853
        children [
          Box {
            size 0.01 0.05 0.09
          }
        ]
      }
      DEF SEC_BBOX Transform {
        translation -0.725 0.0251 -0.62
        rotation 0 1 0 -0.7853
        children [
          Box {
            size 0.01 0.05 0.09
          }
        ]
      }
      DEF YG_BBOX Transform {
        translation -0.855 0.061 0
        children [
          Box {
            size 0.01 0.12 0.42
          }
        ]
      }
      DEF BG_BBOX Transform {
        translation 0.855 0.061 0
        children [
          Box {
            size 0.01 0.12 0.42
          }
        ]
      }
      DEF BGS_BBOX Transform {
        translation 0.8 0.061 0.205
        children [
          Box {
            size 0.1 0.12 0.01
          }
        ]
      }
      DEF BGN_BBOX Transform {
        translation 0.8 0.061 -0.205
        children [
          Box {
            size 0.1 0.12 0.01
          }
        ]
      }
      DEF YGS_BBOX Transform {
        translation -0.8 0.061 0.205
        children [
          Box {
            size 0.1 0.12 0.01
          }
        ]
      }
      DEF YGN_BBOX Transform {
        translation -0.8 0.061 -0.205
        children [
          Box {
            size 0.1 0.12 0.01
          }
        ]
      }
    ]
  }
  locked TRUE
}
DEF BALL SoccerBall {
  hidden linearVelocity_0 -0.002056846029071054 2.493104924034143e-05 0.0046278963914644184
  hidden angularVelocity_0 0.22037601864116274 0.018367223883280215 0.09794504900338351
  translation -0.16256421285802197 0.0209183303846494 0.22297557310959926
  rotation 0.9117786833100519 0.07131204173413072 0.4044431052263074 0.28862308035310946
  radius 0.021
  mass 0.05
}
DEF B1 Robot {
  translation -0.7895799984035938 0.03440912291334395 0.024438160687769075
  rotation -0.008206612636156685 0.9485095230745901 0.31664228420388435 -0.21412130277370167
  children [
    HingeJoint {
      jointParameters HingeJointParameters {
        position 13.354016297730663
        axis -1 0 0
        anchor 0.045 -0.0176 0
      }
      device [
        RotationalMotor {
          name "left wheel motor"
        }
        PositionSensor {
          name "left wheel sensor"
        }
      ]
      endPoint Solid {
        translation 0.045 -0.0176 0
        rotation -1 0 0 0.26076068337149233
        children [
          Transform {
            rotation 0 0 1 1.57
            children [
              DEF WHEEL_SHAPE Shape {
                appearance PBRAppearance {
                  roughness 1
                  metalness 0
                }
                geometry Cylinder {
                  height 0.01
                  radius 0.02
                }
              }
            ]
          }
        ]
        name "right wheel"
        boundingObject Transform {
          rotation 0 0 1 1.57
          children [
            USE WHEEL_SHAPE
          ]
        }
        physics DEF WHEEL_PHYSICS Physics {
          density -1
          mass 0.005
        }
        linearVelocity 0.041758515507931915 -0.2271833589493149 0.06462674901565134
        angularVelocity 9.56658646158199 -3.1658442347584357 -1.641910093348475
      }
    }
    HingeJoint {
      jointParameters HingeJointParameters {
        position 197.81939797773586
        axis -1 0 0
        anchor -0.045 -0.0176 0
      }
      device [
        RotationalMotor {
          name "right wheel motor"
        }
        PositionSensor {
          name "right wheel sensor"
        }
      ]
      endPoint Solid {
        translation -0.045 -0.0176 0
        rotation 1 0 0 3.7685858520109057
        children [
          Transform {
            rotation 0 0 1 1.57
            children [
              Shape {
                appearance PBRAppearance {
                  roughness 1
                  metalness 0
                }
                geometry Cylinder {
                  height 0.01
                  radius 0.02
                }
              }
            ]
          }
        ]
        name "left wheel"
        boundingObject Transform {
          rotation 0 0 1 1.57
          children [
            Shape {
              appearance PBRAppearance {
                roughness 1
                metalness 0
              }
              geometry Cylinder {
                height 0.01
                radius 0.02
              }
            }
          ]
        }
        physics USE WHEEL_PHYSICS
        linearVelocity 0.0797646433469206 0.0228694175589107 -0.2242452092127079
        angularVelocity -10.29799021169011 -3.542906987591322 -3.9555153006961916
      }
    }
    DEF BLUE_ROBOT_SHAPE Shape {
      appearance PBRAppearance {
        baseColorMap ImageTexture {
          url [
            "soccer/blue.png"
          ]
        }
        roughness 1
        metalness 0
      }
      geometry Box {
        size 0.075 0.075 0.075
      }
    }
    Receiver {
    }
  ]
  name "b1"
  boundingObject USE BLUE_ROBOT_SHAPE
  physics DEF ROBOT_PHYSICS Physics {
    density -1
    mass 0.2
  }
  controller "soccer_player"
  linearVelocity 0.10865295852755563 -0.10201894962343584 -0.08739568298212459
  angularVelocity -0.36827032461662446 -3.1999771802373913 -2.802785128371946
}
DEF B2 Robot {
  translation 0.0001227148421618151 0.03751603822206831 -0.0008395478334444206
  rotation -0.9999125404798727 6.6250183801787175e-06 0.01322540536982585 0.0004238729164518571
  children [
    HingeJoint {
      jointParameters HingeJointParameters {
        position 64.188961810597
        axis -1 0 0
        anchor 0.045 -0.0176 0
      }
      device [
        RotationalMotor {
          name "left wheel motor"
        }
        PositionSensor {
          name "left wheel sensor"
        }
      ]
      endPoint Solid {
        translation 0.045 -0.0176 0
        rotation -1 0 0 0.8302237388011289
        children [
          Transform {
            rotation 0 0 1 1.57
            children [
              DEF WHEEL_SHAPE Shape {
                appearance PBRAppearance {
                  roughness 1
                  metalness 0
                }
                geometry Cylinder {
                  height 0.01
                  radius 0.02
                }
              }
            ]
          }
        ]
        name "right wheel"
        boundingObject Transform {
          rotation 0 0 1 1.57
          children [
            USE WHEEL_SHAPE
          ]
        }
        physics DEF WHEEL_PHYSICS Physics {
          density -1
          mass 0.005
        }
        linearVelocity 2.649676210797028e-15 -2.664107323681413e-16 -1.7133865240003957e-14
        angularVelocity -9.439681835281716e-13 3.0846889033294326e-13 -7.712079707593326e-15
      }
    }
    HingeJoint {
      jointParameters HingeJointParameters {
        position 43.58087281622774
        axis -1 0 0
        anchor -0.045 -0.0176 0
      }
      device [
        RotationalMotor {
          name "right wheel motor"
        }
        PositionSensor {
          name "right wheel sensor"
        }
      ]
      endPoint Solid {
        translation -0.045 -0.0176 0
        rotation -0.9999999999999999 0 0 5.3557069731502205
        children [
          Transform {
            rotation 0 0 1 1.57
            children [
              Shape {
                appearance PBRAppearance {
                  roughness 1
                  metalness 0
                }
                geometry Cylinder {
                  height 0.01
                  radius 0.02
                }
              }
            ]
          }
        ]
        name "left wheel"
        boundingObject Transform {
          rotation 0 0 1 1.57
          children [
            Shape {
              appearance PBRAppearance {
                roughness 1
                metalness 0
              }
              geometry Cylinder {
                height 0.01
                radius 0.02
              }
            }
          ]
        }
        physics USE WHEEL_PHYSICS
        linearVelocity 1.886721895445307e-15 7.993440404145785e-16 1.0682641271735295e-14
        angularVelocity 8.461060791533543e-13 3.084789683044876e-13 3.411578720171026e-14
      }
    }
    DEF BLUE_ROBOT_SHAPE Shape {
      appearance PBRAppearance {
        baseColorMap ImageTexture {
          url [
            "soccer/blue.png"
          ]
        }
        roughness 1
        metalness 0
      }
      geometry Box {
        size 0.075 0.075 0.075
      }
    }
    Receiver {
    }
  ]
  name "b2"
  boundingObject USE BLUE_ROBOT_SHAPE
  physics USE ROBOT_PHYSICS
  controller "rcj_soccer_player"
  linearVelocity 2.2438950890673603e-15 1.0658141036401502e-15 -3.830206325211955e-15
  angularVelocity -3.168645901219236e-14 3.0847412777420066e-13 -1.7512033489985868e-15
}
DEF B3 Robot {
  translation 0.7249222697593318 0.03751480647254989 0.037501445508654474
  rotation -2.0477208154034672e-05 0.9999999760920747 -0.0002177074504218638 -2.7994865523581907
  children [
    HingeJoint {
      jointParameters HingeJointParameters {
        position 6.394957768743791
        axis -1 0 0
        anchor 0.045 -0.0176 0
      }
      device [
        RotationalMotor {
          name "left wheel motor"
        }
        PositionSensor {
          name "left wheel sensor"
        }
      ]
      endPoint Solid {
        translation 0.045 -0.0176 0
        rotation -1 0 0 5.868072768743791
        children [
          Transform {
            rotation 0 0 1 1.57
            children [
              DEF WHEEL_SHAPE Shape {
                appearance PBRAppearance {
                  roughness 1
                  metalness 0
                }
                geometry Cylinder {
                  height 0.01
                  radius 0.02
                }
              }
            ]
          }
        ]
        name "right wheel"
        boundingObject Transform {
          rotation 0 0 1 1.57
          children [
            USE WHEEL_SHAPE
          ]
        }
        physics DEF WHEEL_PHYSICS Physics {
          density -1
          mass 0.005
        }
        linearVelocity 0.06709399037679531 9.881576666490492e-06 0.18842835795282925
        angularVelocity 9.420811608226739 -0.00030417737699029205 -3.3542384418399847
      }
    }
    HingeJoint {
      jointParameters HingeJointParameters {
        position 6.394957521084889
        axis -1 0 0
        anchor -0.045 -0.0176 0
      }
      device [
        RotationalMotor {
          name "right wheel motor"
        }
        PositionSensor {
          name "right wheel sensor"
        }
      ]
      endPoint Solid {
        translation -0.045 -0.0176 0
        rotation -1 0 0 5.868903521084889
        children [
          Transform {
            rotation 0 0 1 1.57
            children [
              Shape {
                appearance PBRAppearance {
                  roughness 1
                  metalness 0
                }
                geometry Cylinder {
                  height 0.01
                  radius 0.02
                }
              }
            ]
          }
        ]
        name "left wheel"
        boundingObject Transform {
          rotation 0 0 1 1.57
          children [
            Shape {
              appearance PBRAppearance {
                roughness 1
                metalness 0
              }
              geometry Cylinder {
                height 0.01
                radius 0.02
              }
            }
          ]
        }
        physics USE WHEEL_PHYSICS
        linearVelocity 0.06707652470781446 1.3885830653538996e-05 0.1884346010761889
        angularVelocity 9.420811613355223 -0.0003040206822441041 -3.354238290639758
      }
    }
    DEF BLUE_ROBOT_SHAPE Shape {
      appearance PBRAppearance {
        baseColorMap ImageTexture {
          url [
            "soccer/blue.png"
          ]
        }
        roughness 1
        metalness 0
      }
      geometry Box {
        size 0.075 0.075 0.075
      }
    }
    Receiver {
    }
  ]
  name "b3"
  boundingObject USE BLUE_ROBOT_SHAPE
  physics USE ROBOT_PHYSICS
  controller "soccer_player"
  linearVelocity 0.0670824870509947 9.637361454107336e-06 0.1884339567092194
  angularVelocity 0.00016411492031168838 6.604399102010858e-05 7.241089347612245e-05
}
DEF Y1 Robot {
  translation -0.6268674700884296 0.0375035318621282 0.22112165090396707
  rotation -0.004971265146056406 0.9999860816384993 0.0017672159257503216 0.5273575748828216
  children [
    HingeJoint {
      jointParameters HingeJointParameters {
        position 35.05307356004538
        axis -1 0 0
        anchor 0.045 -0.0176 0
      }
      device [
        RotationalMotor {
          name "left wheel motor"
        }
        PositionSensor {
          name "left wheel sensor"
        }
      ]
      endPoint Solid {
        translation 0.045 -0.0176 0
        rotation 1 0 0 3.172923283032139
        children [
          Transform {
            rotation 0 0 1 1.57
            children [
              DEF WHEEL_SHAPE Shape {
                appearance PBRAppearance {
                  roughness 1
                  metalness 0
                }
                geometry Cylinder {
                  height 0.01
                  radius 0.02
                }
              }
            ]
          }
        ]
        name "right wheel"
        boundingObject Transform {
          rotation 0 0 1 1.57
          children [
            USE WHEEL_SHAPE
          ]
        }
        physics DEF WHEEL_PHYSICS Physics {
          density -1
          mass 0.005
        }
        linearVelocity 0.1304689865600639 0.0021920020894847635 0.1767036217423355
        angularVelocity 7.843213464854905 -5.049942685437231 -6.1489552353011705
      }
    }
    HingeJoint {
      jointParameters HingeJointParameters {
        position 197.87023675539103
        axis -1 0 0
        anchor -0.045 -0.0176 0
      }
      device [
        RotationalMotor {
          name "right wheel motor"
        }
        PositionSensor {
          name "right wheel sensor"
        }
      ]
      endPoint Solid {
        translation -0.045 -0.0176 0
        rotation 1 0 0 3.717747074355731
        children [
          Transform {
            rotation 0 0 1 1.57
            children [
              Shape {
                appearance PBRAppearance {
                  roughness 1
                  metalness 0
                }
                geometry Cylinder {
                  height 0.01
                  radius 0.02
                }
              }
            ]
          }
        ]
        name "left wheel"
        boundingObject Transform {
          rotation 0 0 1 1.57
          children [
            Shape {
              appearance PBRAppearance {
                roughness 1
                metalness 0
              }
              geometry Cylinder {
                height 0.01
                radius 0.02
              }
            }
          ]
        }
        physics USE WHEEL_PHYSICS
        linearVelocity -0.13383271008812203 0.0021415810279426153 -0.1778348428109012
        angularVelocity -7.897006988598053 -5.05370930653904 6.19390620608498
      }
    }
    DEF YELLOW_ROBOT_SHAPE Shape {
      appearance PBRAppearance {
        baseColorMap ImageTexture {
          url [
            "soccer/yellow.png"
          ]
        }
        roughness 1
        metalness 0
      }
      geometry Box {
        size 0.075 0.075 0.075
      }
    }
    Receiver {
    }
  ]
  name "y1"
  boundingObject USE YELLOW_ROBOT_SHAPE
  physics USE ROBOT_PHYSICS
  controller "soccer_player"
  linearVelocity -0.001958411754025237 0.002162975755043074 -0.0011530497375757162
  angularVelocity -0.027394095122782867 -4.807229541136937 0.021914046058286767
}
DEF Y2 Robot {
  translation -0.2964296816581858 0.03750480914393661 -0.5898241079673991
  rotation 0.003050399538555017 0.9999946614744455 0.001171360433190554 -0.8854733388600602
  children [
    HingeJoint {
      jointParameters HingeJointParameters {
        position 22.311447389473134
        axis -1 0 0
        anchor 0.045 -0.0176 0
      }
      device [
        RotationalMotor {
          name "left wheel motor"
        }
        PositionSensor {
          name "left wheel sensor"
        }
      ]
      endPoint Solid {
        translation 0.045 -0.0176 0
        rotation 1 0 0 3.3481788392452105
        children [
          Transform {
            rotation 0 0 1 1.57
            children [
              DEF WHEEL_SHAPE Shape {
                appearance PBRAppearance {
                  roughness 1
                  metalness 0
                }
                geometry Cylinder {
                  height 0.01
                  radius 0.02
                }
              }
            ]
          }
        ]
        name "right wheel"
        boundingObject Transform {
          rotation 0 0 1 1.57
          children [
            USE WHEEL_SHAPE
          ]
        }
        physics DEF WHEEL_PHYSICS Physics {
          density -1
          mass 0.005
        }
        linearVelocity -0.1565385038873741 0.0022173016917828464 0.16026431930950902
        angularVelocity 7.3119189533043025 -5.110440093874144 6.768310295832157
      }
    }
    HingeJoint {
      jointParameters HingeJointParameters {
        position 197.8371334540728
        axis -1 0 0
        anchor -0.045 -0.0176 0
      }
      device [
        RotationalMotor {
          name "right wheel motor"
        }
        PositionSensor {
          name "right wheel sensor"
        }
      ]
      endPoint Solid {
        translation -0.045 -0.0176 0
        rotation 0.9999999999999999 0 0 3.7508503756739544
        children [
          Transform {
            rotation 0 0 1 1.57
            children [
              Shape {
                appearance PBRAppearance {
                  roughness 1
                  metalness 0
                }
                geometry Cylinder {
                  height 0.01
                  radius 0.02
                }
              }
            ]
          }
        ]
        name "left wheel"
        boundingObject Transform {
          rotation 0 0 1 1.57
          children [
            Shape {
              appearance PBRAppearance {
                roughness 1
                metalness 0
              }
              geometry Cylinder {
                height 0.01
                radius 0.02
              }
            }
          ]
        }
        physics USE WHEEL_PHYSICS
        linearVelocity 0.15543913675086168 0.0021884824038950436 -0.16079417690731132
        angularVelocity -7.3685722235457085 -5.114205436885921 -6.8182170114387395
      }
    }
    DEF YELLOW_ROBOT_SHAPE Shape {
      appearance PBRAppearance {
        baseColorMap ImageTexture {
          url [
            "soccer/yellow.png"
          ]
        }
        roughness 1
        metalness 0
      }
      geometry Box {
        size 0.075 0.075 0.075
      }
    }
    Receiver {
    }
  ]
  name "y2"
  boundingObject USE YELLOW_ROBOT_SHAPE
  physics USE ROBOT_PHYSICS
  controller "soccer_player"
  linearVelocity 1.9653311243893027e-05 0.002199124820811658 -0.0006654860670494503
  angularVelocity -0.027855505047705526 -4.865306553183581 -0.025529125353080842
}
DEF Y3 Robot {
  translation -0.6898692281472694 0.03751558953585884 0.06698041439983762
  rotation 8.14614174463205e-05 0.9999999811490539 -0.0001762552965538658 3.0995428397843146
  children [
    HingeJoint {
      jointParameters HingeJointParameters {
        position 9.2800008596338
        axis -1 0 0
        anchor 0.045 -0.0176 0
      }
      device [
        RotationalMotor {
          name "left wheel motor"
        }
        PositionSensor {
          name "left wheel sensor"
        }
      ]
      endPoint Solid {
        translation 0.045 -0.0176 0
        rotation 0.9999999999999999 0 0 3.8132547547253717
        children [
          Transform {
            rotation 0 0 1 1.57
            children [
              DEF WHEEL_SHAPE Shape {
                appearance PBRAppearance {
                  roughness 1
                  metalness 0
                }
                geometry Cylinder {
                  height 0.01
                  radius 0.02
                }
              }
            ]
          }
        ]
        name "right wheel"
        boundingObject Transform {
          rotation 0 0 1 1.57
          children [
            USE WHEEL_SHAPE
          ]
        }
        physics DEF WHEEL_PHYSICS Physics {
          density -1
          mass 0.005
        }
        linearVelocity -0.008436470865615489 -5.6050837739274585e-05 0.19979241233882358
        angularVelocity 9.990374978934492 -0.002100426859501409 0.4217383675613986
      }
    }
    HingeJoint {
      jointParameters HingeJointParameters {
        position 9.280000846621855
        axis -1 0 0
        anchor -0.045 -0.0176 0
      }
      device [
        RotationalMotor {
          name "right wheel motor"
        }
        PositionSensor {
          name "right wheel sensor"
        }
      ]
      endPoint Solid {
        translation -0.045 -0.0176 0
        rotation 1 0 0 3.8124237677373176
        children [
          Transform {
            rotation 0 0 1 1.57
            children [
              Shape {
                appearance PBRAppearance {
                  roughness 1
                  metalness 0
                }
                geometry Cylinder {
                  height 0.01
                  radius 0.02
                }
              }
            ]
          }
        ]
        name "left wheel"
        boundingObject Transform {
          rotation 0 0 1 1.57
          children [
            Shape {
              appearance PBRAppearance {
                roughness 1
                metalness 0
              }
              geometry Cylinder {
                height 0.01
                radius 0.02
              }
            }
          ]
        }
        physics USE WHEEL_PHYSICS
        linearVelocity -0.008433060563916565 6.407502019536385e-05 0.1998236660971859
        angularVelocity 9.990375021735765 -0.002100517118756568 0.4217383218137016
      }
    }
    DEF YELLOW_ROBOT_SHAPE Shape {
      appearance PBRAppearance {
        baseColorMap ImageTexture {
          url [
            "soccer/yellow.png"
          ]
        }
        roughness 1
        metalness 0
      }
      geometry Box {
        size 0.075 0.075 0.075
      }
    }
    Receiver {
    }
  ]
  name "y3"
  boundingObject USE YELLOW_ROBOT_SHAPE
  physics USE ROBOT_PHYSICS
  controller "soccer_player"
  linearVelocity -0.008458353293234954 3.4445990605291703e-06 0.19979426069625825
  angularVelocity -0.000783903907033994 -0.00038426089348595806 0.0013327038570034736
}
Robot {
  children [
    Emitter {
      range 10
      baudRate 115200
    }
  ]
  controller "rcj_soccer_referee_supervisor"
  supervisor TRUE
}
