#VRML_SIM R2022b utf8

EXTERNPROTO "https://raw.githubusercontent.com/cyberbotics/webots/R2023a/projects/objects/backgrounds/protos/TexturedBackground.proto"
EXTERNPROTO "https://raw.githubusercontent.com/cyberbotics/webots/R2023a/projects/objects/backgrounds/protos/TexturedBackgroundLight.proto"

WorldInfo {
  info [
    "A simple RCJ Soccer game simulated using Webots."
  ]
  title "RCJ Soccer Sim"
  basicTimeStep 8
  contactProperties [
    ContactProperties {
      material1 "ball"
      material2 "field"
      coulombFriction [
        1.2
      ]
    }
    ContactProperties {
      material1 "dribbler"
      material2 "ball"
      coulombFriction [
        -1
      ]
      bounce 0
      bounceVelocity 0
    }
    ContactProperties {
      material1 "field"
      material2 "wheel"
      coulombFriction [
        5000
      ]
      bounce 0
      bounceVelocity 0
      forceDependentSlip [
        1
      ]
    }
  ]
}
Viewpoint {
  orientation -0.7128296450606456 0.0002838054276776868 0.701337163265425 3.1410384086685252
  position -0.089841 7.54142e-05 4.4
}
TexturedBackground {
}
TexturedBackgroundLight {
}
DEF SOCCER_FIELD Solid {
  children [
    DEF GROUND Transform {
      rotation 0 0 1 1.5707996938995747
      children [
        Shape {
          appearance PBRAppearance {
            baseColorMap ImageTexture {
              url [
                "soccer/soccer-256.jpg"
              ]
            }
            roughness 1
            metalness 0
          }
          geometry Plane {
            size 1.5 1.5
          }
        }
      ]
    }
    DEF YELLOW_GOAL_GROUND Shape {
      appearance PBRAppearance {
        baseColorMap ImageTexture {
          url [
            "soccer/soccer-256.jpg"
          ]
        }
        roughness 1
        metalness 0
      }
      geometry IndexedFaceSet {
        coord Coordinate {
          point [
            -0.75 -0.95 0
            -0.75 -0.75 0
            0.75 -0.75 0
            0.75 -0.95 0
          ]
        }
        texCoord TextureCoordinate {
          point [
            0 0
            0 0
            0 0
            0 0
          ]
        }
        ccw FALSE
        coordIndex [
          0, 1, 2, 3
        ]
        texCoordIndex [
          0, 1, 2, 3
        ]
      }
    }
    DEF BLUE_GOAL_GROUND Shape {
      appearance PBRAppearance {
        baseColorMap ImageTexture {
          url [
            "soccer/soccer-256.jpg"
          ]
        }
        roughness 1
        metalness 0
      }
      geometry IndexedFaceSet {
        coord Coordinate {
          point [
            -0.75 0.95 0
            -0.75 0.75 0
            0.75 0.75 0
            0.75 0.95 0
          ]
        }
        texCoord TextureCoordinate {
          point [
            0 0
            0 0
            0 0
            0 0
          ]
        }
        coordIndex [
          0, 1, 2, 3
        ]
        texCoordIndex [
          0, 1, 2, 3
        ]
      }
    }
    DEF NORTH_WALL Shape {
      appearance DEF WALL_APPEARANCE PBRAppearance {
        baseColor 0.388235 0.388235 0.388235
        roughness 1
        metalness 0
      }
      geometry IndexedFaceSet {
        coord Coordinate {
          point [
            -0.66 -0.76 0
            -0.21 -0.76 0
            -0.21 -0.75 0
            -0.59 -0.75 0
            -0.65 -0.69 0
            -0.65 0.69 0
            -0.59 0.75 0
            -0.21 0.75 0
            -0.21 0.76 0
            -0.65 0.76 0
            -0.66 0.76 0
            -0.66 -0.76 0.09
            -0.21 -0.76 0.09
            -0.21 -0.75 0.09
            -0.59 -0.75 0.09
            -0.65 -0.69 0.09
            -0.65 0.69 0.09
            -0.59 0.75 0.09
            -0.21 0.75 0.09
            -0.21 0.76 0.09
            -0.65 0.76 0.09
            -0.66 0.76 0.09
          ]
        }
        coordIndex [
          0, 10, 9, -1, 9, 8, 7, -1, 9, 7, 6, -1, 2, 1, 0, -1, 3, 2, 0, -1, 9, 6, 5, -1, 4, 3, 0, -1, 0, 9, 5, -1, 0, 5, 4, -1, 11, 12, 13, -1, 11, 13, 14, -1, 20, 21, 11, -1, 18, 19, 20, -1, 17, 18, 20, -1, 11, 14, 15, -1, 16, 17, 20, -1, 11, 15, 16, -1, 11, 16, 20, -1, 0, 1, 12, 11, -1, 1, 2, 13, 12, -1, 2, 3, 14, 13, -1, 3, 4, 15, 14, -1, 4, 5, 16, 15, -1, 5, 6, 17, 16, -1, 6, 7, 18, 17, -1, 7, 8, 19, 18, -1, 8, 9, 20, 19, -1, 9, 10, 21, 20, -1, 10, 0, 11, 21, -1
        ]
      }
    }
    DEF SOUTH_WALL Shape {
      appearance USE WALL_APPEARANCE
      geometry IndexedFaceSet {
        coord Coordinate {
          point [
            0.66 -0.76 0
            0.66 0.76 0
            0.65 0.76 0
            0.21 0.76 0
            0.21 0.75 0
            0.59 0.75 0
            0.65 0.69 0
            0.65 -0.69 0
            0.59 -0.75 0
            0.21 -0.75 0
            0.21 -0.76 0
            0.66 -0.76 0.09
            0.66 0.76 0.09
            0.65 0.76 0.09
            0.21 0.76 0.09
            0.21 0.75 0.09
            0.59 0.75 0.09
            0.65 0.69 0.09
            0.65 -0.69 0.09
            0.59 -0.75 0.09
            0.21 -0.75 0.09
            0.21 -0.76 0.09
          ]
        }
        coordIndex [
          0, 10, 9, -1, 0, 9, 8, -1, 2, 1, 0, -1, 4, 3, 2, -1, 5, 4, 2, -1, 0, 8, 7, -1, 6, 5, 2, -1, 0, 7, 6, -1, 0, 6, 2, -1, 11, 12, 13, -1, 13, 14, 15, -1, 13, 15, 16, -1, 20, 21, 11, -1, 19, 20, 11, -1, 13, 16, 17, -1, 18, 19, 11, -1, 11, 13, 17, -1, 11, 17, 18, -1, 0, 1, 12, 11, -1, 1, 2, 13, 12, -1, 2, 3, 14, 13, -1, 3, 4, 15, 14, -1, 4, 5, 16, 15, -1, 5, 6, 17, 16, -1, 6, 7, 18, 17, -1, 7, 8, 19, 18, -1, 8, 9, 20, 19, -1, 9, 10, 21, 20, -1, 10, 0, 11, 21, -1
        ]
      }
    }
    DEF YELLOW_GOAL Shape {
      appearance PBRAppearance {
        baseColor 1 1 0
        roughness 1
        metalness 0
      }
      geometry IndexedFaceSet {
        coord Coordinate {
          point [
            -0.21 -0.86 0
            0.21 -0.86 0
            0.21 -0.75 0
            0.2 -0.75 0
            0.2 -0.85 0
            -0.2 -0.85 0
            -0.2 -0.75 0
            -0.21 -0.75 0
            -0.21 -0.86 0
            -0.21 -0.86 0.12
            0.21 -0.86 0.12
            0.21 -0.75 0.12
            0.2 -0.75 0.12
            0.2 -0.85 0.12
            -0.2 -0.85 0.12
            -0.2 -0.75 0.12
            -0.21 -0.75 0.12
            -0.21 -0.86 0.12
          ]
        }
        coordIndex [
          0, 1, 2, 3, 4, 5, 6, 7, 8, -1, 0, 1, 10, 9, -1, 1, 2, 11, 10, -1, 2, 3, 12, 11, -1, 3, 4, 13, 12, -1, 4, 5, 14, 13, -1, 5, 6, 15, 14, -1, 6, 7, 16, 15, -1, 7, 8, 17, 16, -1
        ]
      }
    }
    DEF BLUE_GOAL Shape {
      appearance PBRAppearance {
        baseColor 0 0 1
        roughness 1
        metalness 0
      }
      geometry IndexedFaceSet {
        coord Coordinate {
          point [
            -0.21 0.86 0
            -0.21 0.75 0
            -0.2 0.75 0
            -0.2 0.85 0
            0.2 0.85 0
            0.2 0.75 0
            0.21 0.75 0
            0.21 0.86 0
            -0.21 0.86 0
            -0.21 0.86 0.12
            -0.21 0.75 0.12
            -0.2 0.75 0.12
            -0.2 0.85 0.12
            0.2 0.85 0.12
            0.2 0.75 0.12
            0.21 0.75 0.12
            0.21 0.86 0.12
            -0.21 0.86 0.12
          ]
        }
        coordIndex [
          0, 1, 2, 3, 4, 5, 6, 7, 8, -1, 0, 1, 10, 9, -1, 1, 2, 11, 10, -1, 2, 3, 12, 11, -1, 3, 4, 13, 12, -1, 4, 5, 14, 13, -1, 5, 6, 15, 14, -1, 6, 7, 16, 15, -1, 7, 8, 17, 16, -1
        ]
      }
    }
  ]
  name "soccer field"
  contactMaterial "field"
  boundingObject Group {
    children [
      USE GROUND
      DEF NOTH_BBOX Transform {
        translation 0.655 0 0.045
        children [
          Box {
            size 0.01 1.5 0.09
          }
        ]
      }
      DEF SOUTH_BBOX Transform {
        translation -0.655 0 0.045
        children [
          Box {
            size 0.01 1.5 0.09
          }
        ]
      }
      DEF NW_BBOX Transform {
        translation 0.43 0.755 0.045
        children [
          Box {
            size 0.435 0.01 0.09
          }
        ]
      }
      DEF NE_BBOX Transform {
        translation 0.43 -0.755 0.045
        children [
          Box {
            size 0.435 0.01 0.09
          }
        ]
      }
      DEF SW_BBOX Transform {
        translation -0.43 0.755 0.045
        children [
          Box {
            size 0.435 0.01 0.09
          }
        ]
      }
      DEF SE_BBOX Transform {
        translation -0.43 -0.755 0.045
        children [
          Box {
            size 0.435 0.01 0.09
          }
        ]
      }
      DEF NWC_BBOX Transform {
        translation -0.62 -0.725 0.045
        rotation 0 0 1 -0.7853
        children [
          Box {
            size 0.09 0.01 0.09
          }
        ]
      }
      DEF NEC_BBOX Transform {
        translation -0.62 0.725 0.045
        rotation 0 0 1 0.7853
        children [
          Box {
            size 0.09 0.01 0.09
          }
        ]
      }
      DEF SWC_BBOX Transform {
        translation 0.62 -0.725 0.045
        rotation 0 0 1 0.7853
        children [
          Box {
            size 0.09 0.01 0.09
          }
        ]
      }
      DEF SEC_BBOX Transform {
        translation 0.62 0.725 0.045
        rotation 0 0 1 -0.7853
        children [
          Box {
            size 0.09 0.01 0.09
          }
        ]
      }
      DEF YG_BBOX Transform {
        translation 0 0.855 0.061
        children [
          Box {
            size 0.42 0.01 0.12
          }
        ]
      }
      DEF BG_BBOX Transform {
        translation 0 -0.855 0.061
        children [
          Box {
            size 0.42 0.01 0.12
          }
        ]
      }
      DEF BGS_BBOX Transform {
        translation -0.205 -0.8 0.061
        children [
          Box {
            size 0.01 0.1 0.12
          }
        ]
      }
      DEF BGN_BBOX Transform {
        translation 0.205 -0.8 0.061
        children [
          Box {
            size 0.01 0.1 0.12
          }
        ]
      }
      DEF YGS_BBOX Transform {
        translation -0.205 0.8 0.061
        children [
          Box {
            size 0.01 0.1 0.12
          }
        ]
      }
      DEF YGN_BBOX Transform {
        translation 0.205 0.8 0.061
        children [
          Box {
            size 0.01 0.1 0.12
          }
        ]
      }
    ]
  }
  locked TRUE
}
DEF BALL Robot {
  rotation 0.9050378357439983 -0.4251093124058043 -0.013732748366004924 1.6867606192599456
  children [
    DEF FOOTBALL_SHAPE Shape {
      appearance PBRAppearance {
        baseColorMap ImageTexture {
          url [
            "soccer/football_base_color.jpg"
          ]
        }
        roughness 0.4
        metalness 0
        normalMap ImageTexture {
          url [
            "soccer/football_normal.jpg"
          ]
        }
      }
      geometry Sphere {
        radius 0.015
        subdivision 3
      }
    }
    Emitter {
      name "ball emitter"
      type "infra-red"
      range 0.6
      channel 4
      baudRate 115200
      allowedChannels [
        4
      ]
    }
  ]
  name "soccer ball"
  model "soccer ball"
  contactMaterial "ball"
  boundingObject USE FOOTBALL_SHAPE
  physics Physics {
    density -1
    mass 0.05
  }
  recognitionColors [
    1 1 1
    0 0 0
  ]
  controller "rcj_soccer_ball"
  synchronization FALSE
}
DEF B1 Robot {
  translation 0.26853922009622855 0.3701902491133142 0.0380918
  rotation 0 0 -1 1.5699999999999998
  children [
    DEF FRONT_LEFT_WHEEL HingeJoint {
      jointParameters HingeJointParameters {
        axis 0.7854 0.7854 0
        anchor 0.0304039 0.0304039 -0.032
      }
      device [
        RotationalMotor {
          name "front left motor"
          maxVelocity 40
        }
        PositionSensor {
          name "front left sensor"
        }
      ]
      endPoint Solid {
        translation 0.030695605419343613 0.030763094468236597 -0.03209706454636311
        rotation -0.2848211437594383 0.6958154303567996 0.6593313301709143 3.7007073125004357
        children [
          DEF FRONT_LEFT_TRANSFORM Transform {
            rotation 0 1 0 1.570796327
            children [
              DEF WHEEL_SHAPE Shape {
                appearance PBRAppearance {
                  roughness 1
                  metalness 0
                }
                geometry Cylinder {
                  height 0.006
                  radius 0.0065
                }
              }
            ]
          }
        ]
        name "front left wheel"
        contactMaterial "wheel"
        boundingObject USE FRONT_LEFT_TRANSFORM
        physics DEF WHEEL_PHYSICS Physics {
        }
      }
    }
    DEF REAR_LEFT_WHEEL HingeJoint {
      jointParameters HingeJointParameters {
        axis -0.7854 0.7854 0
        anchor -0.0304039 0.0304039 -0.032
      }
      device [
        RotationalMotor {
          name "rear left motor"
          maxVelocity 40
        }
        PositionSensor {
          name "rear left sensor"
        }
      ]
      endPoint Solid {
        translation -0.030672489460413233 0.030772320041536072 -0.032101226672410846
        rotation -0.918917721027516 0.38243791014011075 -0.09659951795563224 2.7397990222179445
        children [
          DEF REAR_LEFT_TRANSFORM Transform {
            rotation 0 1 0 1.570796327
            children [
              USE WHEEL_SHAPE
            ]
          }
        ]
        name "rear left wheel"
        contactMaterial "wheel"
        boundingObject USE REAR_LEFT_TRANSFORM
        physics USE WHEEL_PHYSICS
      }
    }
    DEF REAR_RIGHT_WHEEL HingeJoint {
      jointParameters HingeJointParameters {
        axis -0.7854 -0.7854 0
        anchor -0.0304039 -0.0304039 -0.032
      }
      device [
        RotationalMotor {
          name "rear right motor"
          maxVelocity 40
        }
        PositionSensor {
          name "rear right sensor"
        }
      ]
      endPoint Solid {
        translation -0.03063832259125643 -0.030795288196791226 -0.03229858299402377
        rotation 0.8618727329541556 0.34999226341757 0.3669888387103635 1.626784342800779
        children [
          DEF REAR_RIGHT_TRANSFORM Transform {
            rotation 0 1 0 1.570796327
            children [
              USE WHEEL_SHAPE
            ]
          }
        ]
        name "rear right wheel"
        contactMaterial "wheel"
        boundingObject USE REAR_RIGHT_TRANSFORM
        physics USE WHEEL_PHYSICS
      }
    }
    DEF FRONT_RIGHT_WHEEL HingeJoint {
      jointParameters HingeJointParameters {
        axis 0.7854 -0.7854 0
        anchor 0.0304039 -0.0304039 -0.032
      }
      device [
        RotationalMotor {
          name "front right motor"
          maxVelocity 40
        }
        PositionSensor {
          name "front right sensor"
        }
      ]
      endPoint Solid {
        translation 0.030611575570730996 -0.030854408575283092 -0.032009976637865534
        rotation -0.02222349777668641 -0.067090710396049 -0.9974993497366919 3.9566620384683953
        children [
          DEF FRONT_RIGHT_TRANSFORM Transform {
            rotation 0 1 0 1.570796327
            children [
              USE WHEEL_SHAPE
            ]
          }
        ]
        name "front right wheel"
        contactMaterial "wheel"
        boundingObject USE FRONT_RIGHT_TRANSFORM
        physics USE WHEEL_PHYSICS
      }
    }
    DEF DRIBBLER HingeJoint {
      jointParameters HingeJointParameters {
        axis 0 1 0
        anchor 0.026 0 -0.008
        suspensionAxis 0 0 1
      }
      device [
        RotationalMotor {
          name "dribbler motor"
          maxVelocity 50
        }
        PositionSensor {
          name "dribbler sensor"
        }
      ]
      endPoint Solid {
        translation 0.025998987101440007 9.862989322484341e-08 -0.008000329819090136
        rotation -0.7042699741531993 -0.7042842498385091 -0.08937280870410572 3.318905912611113
        children [
          DEF DRIBBLER_TRANSFORM Transform {
            rotation 0 1 0 1.570796327
            children [
              Shape {
                geometry Cylinder {
                  height 0.045
                  radius 0.004
                }
              }
            ]
          }
        ]
        name "dribbler"
        contactMaterial "dribbler"
        boundingObject USE DRIBBLER_TRANSFORM
        physics Physics {
          density -1
          mass 0.12
        }
      }
    }
    DEF KICKER SliderJoint {
      jointParameters JointParameters {
        position 5.551113363043895e-17
        axis 1 0 0
      }
      device [
        LinearMotor {
          name "kicker motor"
          maxVelocity 20
          minPosition -1.3233159677521457e-06
          maxPosition 0.042
          maxForce 10000
        }
        PositionSensor {
          name "kicker sensor"
        }
      ]
      endPoint Solid {
        translation -0.020000060538676423 -0.0004198255103439186 -0.024047867877849537
        rotation -1.1828817079662869e-06 0.9999999999985412 1.2321992147801632e-06 1.5708019984105517
        children [
          DEF KICKER_SHAPE Shape {
            geometry Box {
              size 0.015 0.03 0.03
            }
          }
        ]
        boundingObject USE KICKER_SHAPE
        physics Physics {
          density 70000
        }
      }
    }
    DEF ROBOT_SHAPE Shape {
      appearance PBRAppearance {
        baseColorMap ImageTexture {
          url [
            "soccer/blue.png"
          ]
        }
        roughness 1
        metalness 0
      }
      geometry Mesh {
        url [
          "soccer/Robot Shape.obj"
        ]
      }
    }
    Solid {
      translation 0 0.0385 0.02
      rotation 0 0 1 1.5707903061004251
      children [
        Shape {
          appearance PBRAppearance {
            baseColor 0 0 1
            roughness 1
            metalness 0
          }
          geometry Box {
            size 0.005 0.005 0.005
          }
        }
        DistanceSensor {
          name "distancesensor left"
          lookupTable [
            0 0 0
            1 1000 0.05
          ]
          type "sonar"
        }
      ]
      name "left sonar"
    }
    Solid {
      translation 0 -0.0385 0.02
      rotation 0 0 1 -1.5707996938995747
      children [
        Shape {
          appearance PBRAppearance {
            baseColor 0 0 1
            roughness 1
            metalness 0
          }
          geometry Box {
            size 0.005 0.005 0.005
          }
        }
        DistanceSensor {
          name "distancesensor right"
          lookupTable [
            0 0 0
            1 1000 0.05
          ]
          type "sonar"
        }
      ]
      name "right sonar"
    }
    Solid {
      translation 0.0385 0 0.02
      children [
        Shape {
          appearance PBRAppearance {
            baseColor 0 0 1
            roughness 1
            metalness 0
          }
          geometry Box {
            size 0.005 0.005 0.005
          }
        }
        DistanceSensor {
          name "distancesensor front"
          lookupTable [
            0 0 0
            1 1000 0.05
          ]
          type "sonar"
        }
      ]
      name "front sonar"
    }
    Solid {
      translation -0.0385 0 0.02
      rotation 0 0 1 3.141592653589793
      children [
        Shape {
          appearance PBRAppearance {
            baseColor 0 0 1
            roughness 1
            metalness 0
          }
          geometry Box {
            size 0.005 0.005 0.005
          }
        }
        DistanceSensor {
          name "distancesensor back"
          lookupTable [
            0 0 0
            1 1000 0.05
          ]
          type "sonar"
        }
      ]
      name "back sonar"
    }
    Receiver {
      name "supervisor receiver"
      channel 1
      allowedChannels [
        1
      ]
    }
    Receiver {
      name "team receiver"
      channel 2
      allowedChannels [
        2
      ]
    }
    Receiver {
      name "ball receiver"
      type "infra-red"
      channel 4
      allowedChannels [
        4
      ]
    }
    Emitter {
      name "team emitter"
      range 10
      channel 2
      baudRate 115200
      allowedChannels [
        2
      ]
    }
    GPS {
    }
    Compass {
    }
  ]
  name "B1"
  boundingObject USE ROBOT_SHAPE
  physics DEF ROBOT_PHYSICS Physics {
    density 17000
    centerOfMass [
      0 0 -0.1
    ]
    damping Damping {
    }
  }
  controller "rcj_soccer_team_blue"
  synchronization FALSE
}
DEF B2 Robot {
  translation -0.2814879492703363 0.2568677785860409 0.0380918
  rotation 0 0 -1 1.5699999999999998
  children [
    DEF FRONT_LEFT_WHEEL HingeJoint {
      jointParameters HingeJointParameters {
        axis 0.7854 0.7854 0
        anchor 0.0304039 0.0304039 -0.032
      }
      device [
        RotationalMotor {
          name "front left motor"
          maxVelocity 40
        }
        PositionSensor {
          name "front left sensor"
        }
      ]
      endPoint Solid {
        translation 0.030695605419343613 0.030763094468236597 -0.03209706454636311
        rotation -0.2848211437594383 0.6958154303567996 0.6593313301709143 3.7007073125004357
        children [
          DEF FRONT_LEFT_TRANSFORM Transform {
            rotation 0 1 0 1.570796327
            children [
              DEF WHEEL_SHAPE Shape {
                appearance PBRAppearance {
                  roughness 1
                  metalness 0
                }
                geometry Cylinder {
                  height 0.006
                  radius 0.0065
                }
              }
            ]
          }
        ]
        name "front left wheel"
        contactMaterial "wheel"
        boundingObject USE FRONT_LEFT_TRANSFORM
        physics DEF WHEEL_PHYSICS Physics {
        }
      }
    }
    DEF REAR_LEFT_WHEEL HingeJoint {
      jointParameters HingeJointParameters {
        axis -0.7854 0.7854 0
        anchor -0.0304039 0.0304039 -0.032
      }
      device [
        RotationalMotor {
          name "rear left motor"
          maxVelocity 40
        }
        PositionSensor {
          name "rear left sensor"
        }
      ]
      endPoint Solid {
        translation -0.030672489460413233 0.030772320041536017 -0.032101226672410846
        rotation -0.918917721027516 0.38243791014011075 -0.09659951795563224 2.7397990222179445
        children [
          DEF REAR_LEFT_TRANSFORM Transform {
            rotation 0 1 0 1.570796327
            children [
              USE WHEEL_SHAPE
            ]
          }
        ]
        name "rear left wheel"
        contactMaterial "wheel"
        boundingObject USE REAR_LEFT_TRANSFORM
        physics USE WHEEL_PHYSICS
      }
    }
    DEF REAR_RIGHT_WHEEL HingeJoint {
      jointParameters HingeJointParameters {
        axis -0.7854 -0.7854 0
        anchor -0.0304039 -0.0304039 -0.032
      }
      device [
        RotationalMotor {
          name "rear right motor"
          maxVelocity 40
        }
        PositionSensor {
          name "rear right sensor"
        }
      ]
      endPoint Solid {
        translation -0.030638322591256206 -0.03079528819679128 -0.03229858299402377
        rotation 0.8618727329541556 0.34999226341757 0.3669888387103635 1.626784342800779
        children [
          DEF REAR_RIGHT_TRANSFORM Transform {
            rotation 0 1 0 1.570796327
            children [
              USE WHEEL_SHAPE
            ]
          }
        ]
        name "rear right wheel"
        contactMaterial "wheel"
        boundingObject USE REAR_RIGHT_TRANSFORM
        physics USE WHEEL_PHYSICS
      }
    }
    DEF FRONT_RIGHT_WHEEL HingeJoint {
      jointParameters HingeJointParameters {
        axis 0.7854 -0.7854 0
        anchor 0.0304039 -0.0304039 -0.032
      }
      device [
        RotationalMotor {
          name "front right motor"
          maxVelocity 40
        }
        PositionSensor {
          name "front right sensor"
        }
      ]
      endPoint Solid {
        translation 0.030611575570730996 -0.030854408575283092 -0.032009976637865534
        rotation -0.02222349777668641 -0.067090710396049 -0.9974993497366919 3.9566620384683953
        children [
          DEF FRONT_RIGHT_TRANSFORM Transform {
            rotation 0 1 0 1.570796327
            children [
              USE WHEEL_SHAPE
            ]
          }
        ]
        name "front right wheel"
        contactMaterial "wheel"
        boundingObject USE FRONT_RIGHT_TRANSFORM
        physics USE WHEEL_PHYSICS
      }
    }
    DEF DRIBBLER HingeJoint {
      jointParameters HingeJointParameters {
        axis 0 1 0
        anchor 0.026 0 -0.008
        suspensionAxis 0 0 1
      }
      device [
        RotationalMotor {
          name "dribbler motor"
          maxVelocity 50
        }
        PositionSensor {
          name "dribbler sensor"
        }
      ]
      endPoint Solid {
        translation 0.025998987101440007 9.862989322484341e-08 -0.008000329819090136
        rotation -0.7042699741531993 -0.7042842498385091 -0.08937280870410572 3.318905912611113
        children [
          DEF DRIBBLER_TRANSFORM Transform {
            rotation 0 1 0 1.570796327
            children [
              Shape {
                geometry Cylinder {
                  height 0.045
                  radius 0.004
                }
              }
            ]
          }
        ]
        name "dribbler"
        contactMaterial "dribbler"
        boundingObject USE DRIBBLER_TRANSFORM
        physics Physics {
          density -1
          mass 0.12
        }
      }
    }
    DEF KICKER SliderJoint {
      jointParameters JointParameters {
        axis 1 0 0
      }
      device [
        LinearMotor {
          name "kicker motor"
          maxVelocity 20
          minPosition -1.3233159677521457e-06
          maxPosition 0.042
          maxForce 10000
        }
        PositionSensor {
          name "kicker sensor"
        }
      ]
      endPoint Solid {
        translation -0.020000060538676367 -0.0004198255103440296 -0.024047867877849537
        rotation -1.1828817079662869e-06 0.9999999999985412 1.2321992147801632e-06 1.5708019984105517
        children [
          DEF KICKER_SHAPE Shape {
            geometry Box {
              size 0.015 0.03 0.03
            }
          }
        ]
        boundingObject USE KICKER_SHAPE
        physics Physics {
          density 70000
        }
      }
    }
    DEF ROBOT_SHAPE Shape {
      appearance PBRAppearance {
        baseColorMap ImageTexture {
          url [
            "soccer/blue.png"
          ]
        }
        roughness 1
        metalness 0
      }
      geometry Mesh {
        url [
          "soccer/Robot Shape.obj"
        ]
      }
    }
    Solid {
      translation 0 0.0385 0.02
      rotation 0 0 1 1.5707903061004251
      children [
        Shape {
          appearance PBRAppearance {
            baseColor 0 0 1
            roughness 1
            metalness 0
          }
          geometry Box {
            size 0.005 0.005 0.005
          }
        }
        DistanceSensor {
          name "distancesensor left"
          lookupTable [
            0 0 0
            1 1000 0.05
          ]
          type "sonar"
        }
      ]
      name "left sonar"
    }
    Solid {
      translation 0 -0.0385 0.02
      rotation 0 0 1 -1.5707996938995747
      children [
        Shape {
          appearance PBRAppearance {
            baseColor 0 0 1
            roughness 1
            metalness 0
          }
          geometry Box {
            size 0.005 0.005 0.005
          }
        }
        DistanceSensor {
          name "distancesensor right"
          lookupTable [
            0 0 0
            1 1000 0.05
          ]
          type "sonar"
        }
      ]
      name "right sonar"
    }
    Solid {
      translation 0.0385 0 0.02
      children [
        Shape {
          appearance PBRAppearance {
            baseColor 0 0 1
            roughness 1
            metalness 0
          }
          geometry Box {
            size 0.005 0.005 0.005
          }
        }
        DistanceSensor {
          name "distancesensor front"
          lookupTable [
            0 0 0
            1 1000 0.05
          ]
          type "sonar"
        }
      ]
      name "front sonar"
    }
    Solid {
      translation -0.0385 0 0.02
      rotation 0 0 1 3.141592653589793
      children [
        Shape {
          appearance PBRAppearance {
            baseColor 0 0 1
            roughness 1
            metalness 0
          }
          geometry Box {
            size 0.005 0.005 0.005
          }
        }
        DistanceSensor {
          name "distancesensor back"
          lookupTable [
            0 0 0
            1 1000 0.05
          ]
          type "sonar"
        }
      ]
      name "back sonar"
    }
    Receiver {
      name "supervisor receiver"
      channel 1
      allowedChannels [
        1
      ]
    }
    Receiver {
      name "team receiver"
      channel 2
      allowedChannels [
        2
      ]
    }
    Receiver {
      name "ball receiver"
      type "infra-red"
      channel 4
      allowedChannels [
        4
      ]
    }
    Emitter {
      name "team emitter"
      range 10
      channel 2
      baudRate 115200
      allowedChannels [
        2
      ]
    }
    GPS {
    }
    Compass {
    }
  ]
  name "B2"
  boundingObject USE ROBOT_SHAPE
  physics DEF ROBOT_PHYSICS Physics {
    density 17000
    centerOfMass [
      0 0 -0.1
    ]
    damping Damping {
    }
  }
  controller "rcj_soccer_team_blue"
  synchronization FALSE
}
DEF B3 Robot {
  translation -0.05456994904755506 0.27837303278241243 0.0380918
  rotation 0 0 -1 1.5699999999999998
  children [
    DEF FRONT_LEFT_WHEEL HingeJoint {
      jointParameters HingeJointParameters {
        axis 0.7854 0.7854 0
        anchor 0.0304039 0.0304039 -0.032
      }
      device [
        RotationalMotor {
          name "front left motor"
          maxVelocity 40
        }
        PositionSensor {
          name "front left sensor"
        }
      ]
      endPoint Solid {
        translation 0.030695605419343613 0.030763094468236597 -0.03209706454636311
        rotation -0.2848211437594383 0.6958154303567996 0.6593313301709143 3.7007073125004357
        children [
          DEF FRONT_LEFT_TRANSFORM Transform {
            rotation 0 1 0 1.570796327
            children [
              DEF WHEEL_SHAPE Shape {
                appearance PBRAppearance {
                  roughness 1
                  metalness 0
                }
                geometry Cylinder {
                  height 0.006
                  radius 0.0065
                }
              }
            ]
          }
        ]
        name "front left wheel"
        contactMaterial "wheel"
        boundingObject USE FRONT_LEFT_TRANSFORM
        physics DEF WHEEL_PHYSICS Physics {
        }
      }
    }
    DEF REAR_LEFT_WHEEL HingeJoint {
      jointParameters HingeJointParameters {
        axis -0.7854 0.7854 0
        anchor -0.0304039 0.0304039 -0.032
      }
      device [
        RotationalMotor {
          name "rear left motor"
          maxVelocity 40
        }
        PositionSensor {
          name "rear left sensor"
        }
      ]
      endPoint Solid {
        translation -0.030672489460413233 0.03077232004153604 -0.032101226672410846
        rotation -0.918917721027516 0.38243791014011075 -0.09659951795563224 2.7397990222179445
        children [
          DEF REAR_LEFT_TRANSFORM Transform {
            rotation 0 1 0 1.570796327
            children [
              USE WHEEL_SHAPE
            ]
          }
        ]
        name "rear left wheel"
        contactMaterial "wheel"
        boundingObject USE REAR_LEFT_TRANSFORM
        physics USE WHEEL_PHYSICS
      }
    }
    DEF REAR_RIGHT_WHEEL HingeJoint {
      jointParameters HingeJointParameters {
        axis -0.7854 -0.7854 0
        anchor -0.0304039 -0.0304039 -0.032
      }
      device [
        RotationalMotor {
          name "rear right motor"
          maxVelocity 40
        }
        PositionSensor {
          name "rear right sensor"
        }
      ]
      endPoint Solid {
        translation -0.030638322591256262 -0.03079528819679131 -0.03229858299402377
        rotation 0.8618727329541556 0.34999226341757 0.3669888387103635 1.626784342800779
        children [
          DEF REAR_RIGHT_TRANSFORM Transform {
            rotation 0 1 0 1.570796327
            children [
              USE WHEEL_SHAPE
            ]
          }
        ]
        name "rear right wheel"
        contactMaterial "wheel"
        boundingObject USE REAR_RIGHT_TRANSFORM
        physics USE WHEEL_PHYSICS
      }
    }
    DEF FRONT_RIGHT_WHEEL HingeJoint {
      jointParameters HingeJointParameters {
        axis 0.7854 -0.7854 0
        anchor 0.0304039 -0.0304039 -0.032
      }
      device [
        RotationalMotor {
          name "front right motor"
          maxVelocity 40
        }
        PositionSensor {
          name "front right sensor"
        }
      ]
      endPoint Solid {
        translation 0.030611575570730996 -0.030854408575283092 -0.032009976637865534
        rotation -0.02222349777668641 -0.067090710396049 -0.9974993497366919 3.9566620384683953
        children [
          DEF FRONT_RIGHT_TRANSFORM Transform {
            rotation 0 1 0 1.570796327
            children [
              USE WHEEL_SHAPE
            ]
          }
        ]
        name "front right wheel"
        contactMaterial "wheel"
        boundingObject USE FRONT_RIGHT_TRANSFORM
        physics USE WHEEL_PHYSICS
      }
    }
    DEF DRIBBLER HingeJoint {
      jointParameters HingeJointParameters {
        axis 0 1 0
        anchor 0.026 0 -0.008
        suspensionAxis 0 0 1
      }
      device [
        RotationalMotor {
          name "dribbler motor"
          maxVelocity 50
        }
        PositionSensor {
          name "dribbler sensor"
        }
      ]
      endPoint Solid {
        translation 0.025998987101440007 9.862989322484341e-08 -0.008000329819090136
        rotation -0.7042699741531993 -0.7042842498385091 -0.08937280870410572 3.318905912611113
        children [
          DEF DRIBBLER_TRANSFORM Transform {
            rotation 0 1 0 1.570796327
            children [
              Shape {
                geometry Cylinder {
                  height 0.045
                  radius 0.004
                }
              }
            ]
          }
        ]
        name "dribbler"
        contactMaterial "dribbler"
        boundingObject USE DRIBBLER_TRANSFORM
        physics Physics {
          density -1
          mass 0.12
        }
      }
    }
    DEF KICKER SliderJoint {
      jointParameters JointParameters {
        position 8.32712331861948e-17
        axis 1 0 0
      }
      device [
        LinearMotor {
          name "kicker motor"
          maxVelocity 20
          minPosition -1.3233159677521457e-06
          maxPosition 0.042
          maxForce 10000
        }
        PositionSensor {
          name "kicker sensor"
        }
      ]
      endPoint Solid {
        translation -0.020000060538676367 -0.00041982551034394633 -0.024047867877849537
        rotation -1.1828817079662869e-06 0.9999999999985412 1.2321992147801632e-06 1.5708019984105517
        children [
          DEF KICKER_SHAPE Shape {
            geometry Box {
              size 0.015 0.03 0.03
            }
          }
        ]
        boundingObject USE KICKER_SHAPE
        physics Physics {
          density 70000
        }
      }
    }
    DEF ROBOT_SHAPE Shape {
      appearance PBRAppearance {
        baseColorMap ImageTexture {
          url [
            "soccer/blue.png"
          ]
        }
        roughness 1
        metalness 0
      }
      geometry Mesh {
        url [
          "soccer/Robot Shape.obj"
        ]
      }
    }
    Solid {
      translation 0 0.0385 0.02
      rotation 0 0 1 1.5707903061004251
      children [
        Shape {
          appearance PBRAppearance {
            baseColor 0 0 1
            roughness 1
            metalness 0
          }
          geometry Box {
            size 0.005 0.005 0.005
          }
        }
        DistanceSensor {
          name "distancesensor left"
          lookupTable [
            0 0 0
            1 1000 0.05
          ]
          type "sonar"
        }
      ]
      name "left sonar"
    }
    Solid {
      translation 0 -0.0385 0.02
      rotation 0 0 1 -1.5707996938995747
      children [
        Shape {
          appearance PBRAppearance {
            baseColor 0 0 1
            roughness 1
            metalness 0
          }
          geometry Box {
            size 0.005 0.005 0.005
          }
        }
        DistanceSensor {
          name "distancesensor right"
          lookupTable [
            0 0 0
            1 1000 0.05
          ]
          type "sonar"
        }
      ]
      name "right sonar"
    }
    Solid {
      translation 0.0385 0 0.02
      children [
        Shape {
          appearance PBRAppearance {
            baseColor 0 0 1
            roughness 1
            metalness 0
          }
          geometry Box {
            size 0.005 0.005 0.005
          }
        }
        DistanceSensor {
          name "distancesensor front"
          lookupTable [
            0 0 0
            1 1000 0.05
          ]
          type "sonar"
        }
      ]
      name "front sonar"
    }
    Solid {
      translation -0.0385 0 0.02
      rotation 0 0 1 3.141592653589793
      children [
        Shape {
          appearance PBRAppearance {
            baseColor 0 0 1
            roughness 1
            metalness 0
          }
          geometry Box {
            size 0.005 0.005 0.005
          }
        }
        DistanceSensor {
          name "distancesensor back"
          lookupTable [
            0 0 0
            1 1000 0.05
          ]
          type "sonar"
        }
      ]
      name "back sonar"
    }
    Receiver {
      name "supervisor receiver"
      channel 1
      allowedChannels [
        1
      ]
    }
    Receiver {
      name "team receiver"
      channel 2
      allowedChannels [
        2
      ]
    }
    Receiver {
      name "ball receiver"
      type "infra-red"
      channel 4
      allowedChannels [
        4
      ]
    }
    Emitter {
      name "team emitter"
      range 10
      channel 2
      baudRate 115200
      allowedChannels [
        2
      ]
    }
    GPS {
    }
    Compass {
    }
  ]
  name "B3"
  boundingObject USE ROBOT_SHAPE
  physics DEF ROBOT_PHYSICS Physics {
    density 17000
    centerOfMass [
      0 0 -0.1
    ]
    damping Damping {
    }
  }
  controller "rcj_soccer_team_blue"
  synchronization FALSE
}
DEF Y1 Robot {
  translation -0.3284781312985175 -0.2747857590960715 0.0380918
  rotation 0 0 1 1.5699999999999998
  children [
    DEF FRONT_LEFT_WHEEL HingeJoint {
      jointParameters HingeJointParameters {
        axis 0.7854 0.7854 0
        anchor 0.0304039 0.0304039 -0.032
      }
      device [
        RotationalMotor {
          name "front left motor"
          maxVelocity 40
        }
        PositionSensor {
          name "front left sensor"
        }
      ]
      endPoint Solid {
        translation 0.030695605419343613 0.030763094468236597 -0.03209706454636311
        rotation -0.2848211437594383 0.6958154303567996 0.6593313301709143 3.7007073125004357
        children [
          DEF FRONT_LEFT_TRANSFORM Transform {
            rotation 0 1 0 1.570796327
            children [
              DEF WHEEL_SHAPE Shape {
                appearance PBRAppearance {
                  roughness 1
                  metalness 0
                }
                geometry Cylinder {
                  height 0.006
                  radius 0.0065
                }
              }
            ]
          }
        ]
        name "front left wheel"
        contactMaterial "wheel"
        boundingObject USE FRONT_LEFT_TRANSFORM
        physics DEF WHEEL_PHYSICS Physics {
        }
      }
    }
    DEF REAR_LEFT_WHEEL HingeJoint {
      jointParameters HingeJointParameters {
        axis -0.7854 0.7854 0
        anchor -0.0304039 0.0304039 -0.032
      }
      device [
        RotationalMotor {
          name "rear left motor"
          maxVelocity 40
        }
        PositionSensor {
          name "rear left sensor"
        }
      ]
      endPoint Solid {
        translation -0.030672489460413344 0.03077232004153596 -0.032101226672410846
        rotation 0.9189177210275162 -0.3824379101401104 0.0965995179556321 -2.7397990222179436
        children [
          DEF REAR_LEFT_TRANSFORM Transform {
            rotation 0 1 0 1.570796327
            children [
              USE WHEEL_SHAPE
            ]
          }
        ]
        name "rear left wheel"
        contactMaterial "wheel"
        boundingObject USE REAR_LEFT_TRANSFORM
        physics USE WHEEL_PHYSICS
      }
    }
    DEF REAR_RIGHT_WHEEL HingeJoint {
      jointParameters HingeJointParameters {
        axis -0.7854 -0.7854 0
        anchor -0.0304039 -0.0304039 -0.032
      }
      device [
        RotationalMotor {
          name "rear right motor"
          maxVelocity 40
        }
        PositionSensor {
          name "rear right sensor"
        }
      ]
      endPoint Solid {
        translation -0.030638322591256317 -0.030795288196791504 -0.03229858299402377
        rotation 0.8618727329541551 0.34999226341757034 0.36698883871036403 1.6267843428007798
        children [
          DEF REAR_RIGHT_TRANSFORM Transform {
            rotation 0 1 0 1.570796327
            children [
              USE WHEEL_SHAPE
            ]
          }
        ]
        name "rear right wheel"
        contactMaterial "wheel"
        boundingObject USE REAR_RIGHT_TRANSFORM
        physics USE WHEEL_PHYSICS
      }
    }
    DEF FRONT_RIGHT_WHEEL HingeJoint {
      jointParameters HingeJointParameters {
        axis 0.7854 -0.7854 0
        anchor 0.0304039 -0.0304039 -0.032
      }
      device [
        RotationalMotor {
          name "front right motor"
          maxVelocity 40
        }
        PositionSensor {
          name "front right sensor"
        }
      ]
      endPoint Solid {
        translation 0.030611575570730996 -0.030854408575283092 -0.032009976637865534
        rotation -0.02222349777668641 -0.067090710396049 -0.9974993497366919 3.9566620384683953
        children [
          DEF FRONT_RIGHT_TRANSFORM Transform {
            rotation 0 1 0 1.570796327
            children [
              USE WHEEL_SHAPE
            ]
          }
        ]
        name "front right wheel"
        contactMaterial "wheel"
        boundingObject USE FRONT_RIGHT_TRANSFORM
        physics USE WHEEL_PHYSICS
      }
    }
    DEF DRIBBLER HingeJoint {
      jointParameters HingeJointParameters {
        axis 0 1 0
        anchor 0.026 0 -0.008
        suspensionAxis 0 0 1
      }
      device [
        RotationalMotor {
          name "dribbler motor"
          maxVelocity 50
        }
        PositionSensor {
          name "dribbler sensor"
        }
      ]
      endPoint Solid {
        translation 0.025998987101440007 9.862989322484341e-08 -0.008000329819090136
        rotation -0.7042699741531993 -0.7042842498385091 -0.08937280870410572 3.318905912611113
        children [
          DEF DRIBBLER_TRANSFORM Transform {
            rotation 0 1 0 1.570796327
            children [
              Shape {
                geometry Cylinder {
                  height 0.045
                  radius 0.004
                }
              }
            ]
          }
        ]
        name "dribbler"
        contactMaterial "dribbler"
        boundingObject USE DRIBBLER_TRANSFORM
        physics Physics {
          density -1
          mass 0.12
        }
      }
    }
    DEF KICKER SliderJoint {
      jointParameters JointParameters {
        axis 1 0 0
      }
      device [
        LinearMotor {
          name "kicker motor"
          maxVelocity 20
          minPosition -1.3233159677521457e-06
          maxPosition 0.042
          maxForce 10000
        }
        PositionSensor {
          name "kicker sensor"
        }
      ]
      endPoint Solid {
        translation -0.020000060538676367 -0.0004198255103440296 -0.024047867877849537
        rotation -1.182881708358809e-06 0.9999999999985413 1.2321992158007204e-06 1.5708019984105515
        children [
          DEF KICKER_SHAPE Shape {
            geometry Box {
              size 0.015 0.03 0.03
            }
          }
        ]
        boundingObject USE KICKER_SHAPE
        physics Physics {
          density 70000
        }
      }
    }
    DEF ROBOT_SHAPE Shape {
      appearance PBRAppearance {
        baseColorMap ImageTexture {
          url [
            "soccer/yellow.png"
          ]
        }
        roughness 1
        metalness 0
      }
      geometry Mesh {
        url [
          "soccer/Robot Shape.obj"
        ]
      }
    }
    Solid {
      translation 0 0.0385 0.02
      rotation 0 0 1 1.5707903061004251
      children [
        Shape {
          appearance PBRAppearance {
            baseColor 0 0 1
            roughness 1
            metalness 0
          }
          geometry Box {
            size 0.005 0.005 0.005
          }
        }
        DistanceSensor {
          name "distancesensor left"
          lookupTable [
            0 0 0
            1 1000 0.05
          ]
          type "sonar"
        }
      ]
      name "left sonar"
    }
    Solid {
      translation 0 -0.0385 0.02
      rotation 0 0 1 -1.5707996938995747
      children [
        Shape {
          appearance PBRAppearance {
            baseColor 0 0 1
            roughness 1
            metalness 0
          }
          geometry Box {
            size 0.005 0.005 0.005
          }
        }
        DistanceSensor {
          name "distancesensor right"
          lookupTable [
            0 0 0
            1 1000 0.05
          ]
          type "sonar"
        }
      ]
      name "right sonar"
    }
    Solid {
      translation 0.0385 0 0.02
      children [
        Shape {
          appearance PBRAppearance {
            baseColor 0 0 1
            roughness 1
            metalness 0
          }
          geometry Box {
            size 0.005 0.005 0.005
          }
        }
        DistanceSensor {
          name "distancesensor front"
          lookupTable [
            0 0 0
            1 1000 0.05
          ]
          type "sonar"
        }
      ]
      name "front sonar"
    }
    Solid {
      translation -0.0385 0 0.02
      rotation 0 0 1 3.141592653589793
      children [
        Shape {
          appearance PBRAppearance {
            baseColor 0 0 1
            roughness 1
            metalness 0
          }
          geometry Box {
            size 0.005 0.005 0.005
          }
        }
        DistanceSensor {
          name "distancesensor back"
          lookupTable [
            0 0 0
            1 1000 0.05
          ]
          type "sonar"
        }
      ]
      name "back sonar"
    }
    Receiver {
      name "supervisor receiver"
      channel 1
      allowedChannels [
        1
      ]
    }
    Receiver {
      name "team receiver"
      channel 2
      allowedChannels [
        2
      ]
    }
    Receiver {
      name "ball receiver"
      type "infra-red"
      channel 4
      allowedChannels [
        4
      ]
    }
    Emitter {
      name "team emitter"
      range 10
      channel 2
      baudRate 115200
      allowedChannels [
        2
      ]
    }
    GPS {
    }
    Compass {
    }
  ]
  name "Y1"
  boundingObject USE ROBOT_SHAPE
  physics DEF ROBOT_PHYSICS Physics {
    density 17000
    centerOfMass [
      0 0 -0.1
    ]
    damping Damping {
    }
  }
  controller "rcj_soccer_team_yellow"
  synchronization FALSE
}
DEF Y2 Robot {
  translation 0.3519502530894836 -0.2365117727563275 0.0380918
  rotation 0 0 1 1.5699999999999998
  children [
    DEF FRONT_LEFT_WHEEL HingeJoint {
      jointParameters HingeJointParameters {
        axis 0.7854 0.7854 0
        anchor 0.0304039 0.0304039 -0.032
      }
      device [
        RotationalMotor {
          name "front left motor"
          maxVelocity 40
        }
        PositionSensor {
          name "front left sensor"
        }
      ]
      endPoint Solid {
        translation 0.030695605419343613 0.030763094468236597 -0.03209706454636311
        rotation -0.2848211437594383 0.6958154303567996 0.6593313301709143 3.7007073125004357
        children [
          DEF FRONT_LEFT_TRANSFORM Transform {
            rotation 0 1 0 1.570796327
            children [
              DEF WHEEL_SHAPE Shape {
                appearance PBRAppearance {
                  roughness 1
                  metalness 0
                }
                geometry Cylinder {
                  height 0.006
                  radius 0.0065
                }
              }
            ]
          }
        ]
        name "front left wheel"
        contactMaterial "wheel"
        boundingObject USE FRONT_LEFT_TRANSFORM
        physics DEF WHEEL_PHYSICS Physics {
        }
      }
    }
    DEF REAR_LEFT_WHEEL HingeJoint {
      jointParameters HingeJointParameters {
        axis -0.7854 0.7854 0
        anchor -0.0304039 0.0304039 -0.032
      }
      device [
        RotationalMotor {
          name "rear left motor"
          maxVelocity 40
        }
        PositionSensor {
          name "rear left sensor"
        }
      ]
      endPoint Solid {
        translation -0.030672489460413233 0.030772320041536017 -0.032101226672410846
        rotation 0.9189177210275162 -0.3824379101401104 0.0965995179556321 -2.7397990222179436
        children [
          DEF REAR_LEFT_TRANSFORM Transform {
            rotation 0 1 0 1.570796327
            children [
              USE WHEEL_SHAPE
            ]
          }
        ]
        name "rear left wheel"
        contactMaterial "wheel"
        boundingObject USE REAR_LEFT_TRANSFORM
        physics USE WHEEL_PHYSICS
      }
    }
    DEF REAR_RIGHT_WHEEL HingeJoint {
      jointParameters HingeJointParameters {
        axis -0.7854 -0.7854 0
        anchor -0.0304039 -0.0304039 -0.032
      }
      device [
        RotationalMotor {
          name "rear right motor"
          maxVelocity 40
        }
        PositionSensor {
          name "rear right sensor"
        }
      ]
      endPoint Solid {
        translation -0.030638322591256262 -0.030795288196791448 -0.03229858299402377
        rotation 0.8618727329541551 0.34999226341757034 0.36698883871036403 1.6267843428007798
        children [
          DEF REAR_RIGHT_TRANSFORM Transform {
            rotation 0 1 0 1.570796327
            children [
              USE WHEEL_SHAPE
            ]
          }
        ]
        name "rear right wheel"
        contactMaterial "wheel"
        boundingObject USE REAR_RIGHT_TRANSFORM
        physics USE WHEEL_PHYSICS
      }
    }
    DEF FRONT_RIGHT_WHEEL HingeJoint {
      jointParameters HingeJointParameters {
        axis 0.7854 -0.7854 0
        anchor 0.0304039 -0.0304039 -0.032
      }
      device [
        RotationalMotor {
          name "front right motor"
          maxVelocity 40
        }
        PositionSensor {
          name "front right sensor"
        }
      ]
      endPoint Solid {
        translation 0.030611575570730996 -0.030854408575283092 -0.032009976637865534
        rotation -0.02222349777668641 -0.067090710396049 -0.9974993497366919 3.9566620384683953
        children [
          DEF FRONT_RIGHT_TRANSFORM Transform {
            rotation 0 1 0 1.570796327
            children [
              USE WHEEL_SHAPE
            ]
          }
        ]
        name "front right wheel"
        contactMaterial "wheel"
        boundingObject USE FRONT_RIGHT_TRANSFORM
        physics USE WHEEL_PHYSICS
      }
    }
    DEF DRIBBLER HingeJoint {
      jointParameters HingeJointParameters {
        axis 0 1 0
        anchor 0.026 0 -0.008
        suspensionAxis 0 0 1
      }
      device [
        RotationalMotor {
          name "dribbler motor"
          maxVelocity 50
        }
        PositionSensor {
          name "dribbler sensor"
        }
      ]
      endPoint Solid {
        translation 0.025998987101440007 9.862989322484341e-08 -0.008000329819090136
        rotation -0.7042699741531993 -0.7042842498385091 -0.08937280870410572 3.318905912611113
        children [
          DEF DRIBBLER_TRANSFORM Transform {
            rotation 0 1 0 1.570796327
            children [
              Shape {
                geometry Cylinder {
                  height 0.045
                  radius 0.004
                }
              }
            ]
          }
        ]
        name "dribbler"
        contactMaterial "dribbler"
        boundingObject USE DRIBBLER_TRANSFORM
        physics Physics {
          density -1
          mass 0.12
        }
      }
    }
    DEF KICKER SliderJoint {
      jointParameters JointParameters {
        axis 1 0 0
      }
      device [
        LinearMotor {
          name "kicker motor"
          maxVelocity 20
          minPosition -1.3233159677521457e-06
          maxPosition 0.042
          maxForce 10000
        }
        PositionSensor {
          name "kicker sensor"
        }
      ]
      endPoint Solid {
        translation -0.0200000605386762 -0.0004198255103440296 -0.024047867877849537
        rotation -1.182881708358809e-06 0.9999999999985413 1.2321992158007204e-06 1.5708019984105515
        children [
          DEF KICKER_SHAPE Shape {
            geometry Box {
              size 0.015 0.03 0.03
            }
          }
        ]
        boundingObject USE KICKER_SHAPE
        physics Physics {
          density 70000
        }
      }
    }
    DEF ROBOT_SHAPE Shape {
      appearance PBRAppearance {
        baseColorMap ImageTexture {
          url [
            "soccer/yellow.png"
          ]
        }
        roughness 1
        metalness 0
      }
      geometry Mesh {
        url [
          "soccer/Robot Shape.obj"
        ]
      }
    }
    Solid {
      translation 0 0.0385 0.02
      rotation 0 0 1 1.5707903061004251
      children [
        Shape {
          appearance PBRAppearance {
            baseColor 0 0 1
            roughness 1
            metalness 0
          }
          geometry Box {
            size 0.005 0.005 0.005
          }
        }
        DistanceSensor {
          name "distancesensor left"
          lookupTable [
            0 0 0
            1 1000 0.05
          ]
          type "sonar"
        }
      ]
      name "left sonar"
    }
    Solid {
      translation 0 -0.0385 0.02
      rotation 0 0 1 -1.5707996938995747
      children [
        Shape {
          appearance PBRAppearance {
            baseColor 0 0 1
            roughness 1
            metalness 0
          }
          geometry Box {
            size 0.005 0.005 0.005
          }
        }
        DistanceSensor {
          name "distancesensor right"
          lookupTable [
            0 0 0
            1 1000 0.05
          ]
          type "sonar"
        }
      ]
      name "right sonar"
    }
    Solid {
      translation 0.0385 0 0.02
      children [
        Shape {
          appearance PBRAppearance {
            baseColor 0 0 1
            roughness 1
            metalness 0
          }
          geometry Box {
            size 0.005 0.005 0.005
          }
        }
        DistanceSensor {
          name "distancesensor front"
          lookupTable [
            0 0 0
            1 1000 0.05
          ]
          type "sonar"
        }
      ]
      name "front sonar"
    }
    Solid {
      translation -0.0385 0 0.02
      rotation 0 0 1 3.141592653589793
      children [
        Shape {
          appearance PBRAppearance {
            baseColor 0 0 1
            roughness 1
            metalness 0
          }
          geometry Box {
            size 0.005 0.005 0.005
          }
        }
        DistanceSensor {
          name "distancesensor back"
          lookupTable [
            0 0 0
            1 1000 0.05
          ]
          type "sonar"
        }
      ]
      name "back sonar"
    }
    Receiver {
      name "supervisor receiver"
      channel 1
      allowedChannels [
        1
      ]
    }
    Receiver {
      name "team receiver"
      channel 2
      allowedChannels [
        2
      ]
    }
    Receiver {
      name "ball receiver"
      type "infra-red"
      channel 4
      allowedChannels [
        4
      ]
    }
    Emitter {
      name "team emitter"
      range 10
      channel 2
      baudRate 115200
      allowedChannels [
        2
      ]
    }
    GPS {
    }
    Compass {
    }
  ]
  name "Y2"
  boundingObject USE ROBOT_SHAPE
  physics DEF ROBOT_PHYSICS Physics {
    density 17000
    centerOfMass [
      0 0 -0.1
    ]
    damping Damping {
    }
  }
  controller "rcj_soccer_team_yellow"
  synchronization FALSE
}
DEF Y3 Robot {
  translation 0 -0.1 0.0380918
  rotation 0 0 1 1.5699999999999998
  children [
    DEF FRONT_LEFT_WHEEL HingeJoint {
      jointParameters HingeJointParameters {
        axis 0.7854 0.7854 0
        anchor 0.0304039 0.0304039 -0.032
      }
      device [
        RotationalMotor {
          name "front left motor"
          maxVelocity 40
        }
        PositionSensor {
          name "front left sensor"
        }
      ]
      endPoint Solid {
        translation 0.030695605419343613 0.030763094468236597 -0.03209706454636311
        rotation -0.2848211437594383 0.6958154303567996 0.6593313301709143 3.7007073125004357
        children [
          DEF FRONT_LEFT_TRANSFORM Transform {
            rotation 0 1 0 1.570796327
            children [
              DEF WHEEL_SHAPE Shape {
                appearance PBRAppearance {
                  roughness 1
                  metalness 0
                }
                geometry Cylinder {
                  height 0.006
                  radius 0.0065
                }
              }
            ]
          }
        ]
        name "front left wheel"
        contactMaterial "wheel"
        boundingObject USE FRONT_LEFT_TRANSFORM
        physics DEF WHEEL_PHYSICS Physics {
        }
      }
    }
    DEF REAR_LEFT_WHEEL HingeJoint {
      jointParameters HingeJointParameters {
        axis -0.7854 0.7854 0
        anchor -0.0304039 0.0304039 -0.032
      }
      device [
        RotationalMotor {
          name "rear left motor"
          maxVelocity 40
        }
        PositionSensor {
          name "rear left sensor"
        }
      ]
      endPoint Solid {
        translation -0.030672489460413233 0.030772320041535982 -0.032101226672410846
        rotation 0.9189177210275162 -0.3824379101401104 0.0965995179556321 -2.7397990222179436
        children [
          DEF REAR_LEFT_TRANSFORM Transform {
            rotation 0 1 0 1.570796327
            children [
              USE WHEEL_SHAPE
            ]
          }
        ]
        name "rear left wheel"
        contactMaterial "wheel"
        boundingObject USE REAR_LEFT_TRANSFORM
        physics USE WHEEL_PHYSICS
      }
    }
    DEF REAR_RIGHT_WHEEL HingeJoint {
      jointParameters HingeJointParameters {
        axis -0.7854 -0.7854 0
        anchor -0.0304039 -0.0304039 -0.032
      }
      device [
        RotationalMotor {
          name "rear right motor"
          maxVelocity 40
        }
        PositionSensor {
          name "rear right sensor"
        }
      ]
      endPoint Solid {
        translation -0.030638322591256317 -0.030795288196791355 -0.03229858299402377
        rotation 0.8618727329541551 0.34999226341757034 0.36698883871036403 1.6267843428007798
        children [
          DEF REAR_RIGHT_TRANSFORM Transform {
            rotation 0 1 0 1.570796327
            children [
              USE WHEEL_SHAPE
            ]
          }
        ]
        name "rear right wheel"
        contactMaterial "wheel"
        boundingObject USE REAR_RIGHT_TRANSFORM
        physics USE WHEEL_PHYSICS
      }
    }
    DEF FRONT_RIGHT_WHEEL HingeJoint {
      jointParameters HingeJointParameters {
        axis 0.7854 -0.7854 0
        anchor 0.0304039 -0.0304039 -0.032
      }
      device [
        RotationalMotor {
          name "front right motor"
          maxVelocity 40
        }
        PositionSensor {
          name "front right sensor"
        }
      ]
      endPoint Solid {
        translation 0.030611575570730996 -0.030854408575283092 -0.032009976637865534
        rotation -0.02222349777668641 -0.067090710396049 -0.9974993497366919 3.9566620384683953
        children [
          DEF FRONT_RIGHT_TRANSFORM Transform {
            rotation 0 1 0 1.570796327
            children [
              USE WHEEL_SHAPE
            ]
          }
        ]
        name "front right wheel"
        contactMaterial "wheel"
        boundingObject USE FRONT_RIGHT_TRANSFORM
        physics USE WHEEL_PHYSICS
      }
    }
    DEF DRIBBLER HingeJoint {
      jointParameters HingeJointParameters {
        axis 0 1 0
        anchor 0.026 0 -0.008
        suspensionAxis 0 0 1
      }
      device [
        RotationalMotor {
          name "dribbler motor"
          maxVelocity 50
        }
        PositionSensor {
          name "dribbler sensor"
        }
      ]
      endPoint Solid {
        translation 0.025998987101440007 9.862989322484341e-08 -0.008000329819090136
        rotation -0.7042699741531993 -0.7042842498385091 -0.08937280870410572 3.318905912611113
        children [
          DEF DRIBBLER_TRANSFORM Transform {
            rotation 0 1 0 1.570796327
            children [
              Shape {
                geometry Cylinder {
                  height 0.045
                  radius 0.004
                }
              }
            ]
          }
        ]
        name "dribbler"
        contactMaterial "dribbler"
        boundingObject USE DRIBBLER_TRANSFORM
        physics Physics {
          density -1
          mass 0.12
        }
      }
    }
    DEF KICKER SliderJoint {
      jointParameters JointParameters {
        position -1.388140960003884e-17
        axis 1 0 0
      }
      device [
        LinearMotor {
          name "kicker motor"
          maxVelocity 20
          minPosition -1.3233159677521457e-06
          maxPosition 0.042
          maxForce 10000
        }
        PositionSensor {
          name "kicker sensor"
        }
      ]
      endPoint Solid {
        translation -0.020000060538676354 -0.0004198255103439872 -0.024047867877849537
        rotation -1.182881708358809e-06 0.9999999999985413 1.2321992158007204e-06 1.5708019984105515
        children [
          DEF KICKER_SHAPE Shape {
            geometry Box {
              size 0.015 0.03 0.03
            }
          }
        ]
        boundingObject USE KICKER_SHAPE
        physics Physics {
          density 70000
        }
      }
    }
    DEF ROBOT_SHAPE Shape {
      appearance PBRAppearance {
        baseColorMap ImageTexture {
          url [
            "soccer/yellow.png"
          ]
        }
        roughness 1
        metalness 0
      }
      geometry Mesh {
        url [
          "soccer/Robot Shape.obj"
        ]
      }
    }
    Solid {
      translation 0 0.0385 0.02
      rotation 0 0 1 1.5707903061004251
      children [
        Shape {
          appearance PBRAppearance {
            baseColor 0 0 1
            roughness 1
            metalness 0
          }
          geometry Box {
            size 0.005 0.005 0.005
          }
        }
        DistanceSensor {
          name "distancesensor left"
          lookupTable [
            0 0 0
            1 1000 0.05
          ]
          type "sonar"
        }
      ]
      name "left sonar"
    }
    Solid {
      translation 0 -0.0385 0.02
      rotation 0 0 1 -1.5707996938995747
      children [
        Shape {
          appearance PBRAppearance {
            baseColor 0 0 1
            roughness 1
            metalness 0
          }
          geometry Box {
            size 0.005 0.005 0.005
          }
        }
        DistanceSensor {
          name "distancesensor right"
          lookupTable [
            0 0 0
            1 1000 0.05
          ]
          type "sonar"
        }
      ]
      name "right sonar"
    }
    Solid {
      translation 0.0385 0 0.02
      children [
        Shape {
          appearance PBRAppearance {
            baseColor 0 0 1
            roughness 1
            metalness 0
          }
          geometry Box {
            size 0.005 0.005 0.005
          }
        }
        DistanceSensor {
          name "distancesensor front"
          lookupTable [
            0 0 0
            1 1000 0.05
          ]
          type "sonar"
        }
      ]
      name "front sonar"
    }
    Solid {
      translation -0.0385 0 0.02
      rotation 0 0 1 3.141592653589793
      children [
        Shape {
          appearance PBRAppearance {
            baseColor 0 0 1
            roughness 1
            metalness 0
          }
          geometry Box {
            size 0.005 0.005 0.005
          }
        }
        DistanceSensor {
          name "distancesensor back"
          lookupTable [
            0 0 0
            1 1000 0.05
          ]
          type "sonar"
        }
      ]
      name "back sonar"
    }
    Receiver {
      name "supervisor receiver"
      channel 1
      allowedChannels [
        1
      ]
    }
    Receiver {
      name "team receiver"
      channel 2
      allowedChannels [
        2
      ]
    }
    Receiver {
      name "ball receiver"
      type "infra-red"
      channel 4
      allowedChannels [
        4
      ]
    }
    Emitter {
      name "team emitter"
      range 10
      channel 2
      baudRate 115200
      allowedChannels [
        2
      ]
    }
    GPS {
    }
    Compass {
    }
  ]
  name "Y3"
  boundingObject USE ROBOT_SHAPE
  physics DEF ROBOT_PHYSICS Physics {
    density 17000
    centerOfMass [
      0 0 -0.1
    ]
    damping Damping {
    }
  }
  controller "rcj_soccer_team_yellow"
  synchronization FALSE
}
Robot {
  children [
    Emitter {
      range 10
      channel 1
      baudRate 115200
      allowedChannels [
        1
      ]
    }
  ]
  controller "rcj_soccer_referee_supervisor"
  supervisor TRUE
}
